<?xml version="1.0"?>
<robot
  name="SAKURA">	
    <!-- camera -->
  <gazebo reference="camera_link">
    <sensor type="camera" name="camera">
      <update_rate>30.0</update_rate>
      <camera name="head">
        <horizontal_fov>1.3962634</horizontal_fov>
        <image>
          <width>800</width>
          <height>800</height>
          <format>R8G8B8</format>
        </image>
        <clip>
          <near>0.02</near>
          <far>300</far>
        </clip>
        <noise>
          <type>gaussian</type>
          <!-- Noise is sampled independently per pixel on each frame.
               That pixel's noise value is added to each of its color
               channels, which at that point lie in the range [0,1]. -->
          <mean>0.0</mean>
          <stddev>0.007</stddev>
        </noise>
      </camera>
      <plugin name="camera_controller" filename="libgazebo_ros_camera.so">
        <alwaysOn>true</alwaysOn>
        <updateRate>0.0</updateRate>
        <cameraName>humanoid/camera</cameraName>
        <imageTopicName>image_raw</imageTopicName>
        <cameraInfoTopicName>camera_info</cameraInfoTopicName>
        <frameName>camera_link</frameName>
        <hackBaseline>0.07</hackBaseline>
        <distortionK1>0.0</distortionK1>
        <distortionK2>0.0</distortionK2>
        <distortionK3>0.0</distortionK3>
        <distortionT1>0.0</distortionT1>
        <distortionT2>0.0</distortionT2>
      </plugin>
    </sensor>
  </gazebo>
  
  <gazebo reference="imu_link">
    <gravity>true</gravity>
    <sensor name="imu_sensor" type="imu">
      <always_on>true</always_on>
      <update_rate>125</update_rate>
      <visualize>true</visualize>
      <topic>__default_topic__</topic>
      <plugin filename="libgazebo_ros_imu_sensor.so" name="imu_plugin">
        <topicName>imu/data_raw</topicName>
        <bodyName>imu_link</bodyName>
        <updateRateHZ>125.0</updateRateHZ>
        <gaussianNoise>0.0</gaussianNoise>
        <xyzOffset>0 0 0</xyzOffset>
        <rpyOffset>0 0 0</rpyOffset>
        <frameName>imu_link</frameName>
      </plugin>
      <pose>0 0 0 0 0 0</pose>
    </sensor>
  </gazebo>
  <gazebo>
    <plugin filename="libgazebo_ros_control.so" name="gazebo_ros_control">
      <robotNamespace>/SAKURA</robotNamespace>
      <robotSimType>gazebo_ros_control/DefaultRobotHWSim</robotSimType>
    </plugin>
  </gazebo>
<gazebo reference="J_HEAD0">
	<stopErp>0.2</stopErp>
  </gazebo>  
  <gazebo reference="J_HEAD1">
	<stopErp>0.2</stopErp>
  </gazebo>  
  <gazebo reference="J_LARM0">
	<stopErp>0.2</stopErp>
  </gazebo>  
  <gazebo reference="J_LARM1">
	<stopErp>0.2</stopErp>
  </gazebo>  
  <gazebo reference="J_LARM2">
	<stopErp>0.2</stopErp>
  </gazebo>  
  <gazebo reference="J_RARM0">
	<stopErp>0.2</stopErp>
  </gazebo>  
  <gazebo reference="J_RARM1">
	<stopErp>0.2</stopErp>
  </gazebo>  
  <gazebo reference="J_LLEG0">
	<stopErp>0.2</stopErp>
	<provideFeedback>true</provideFeedback>
  </gazebo>  
  <gazebo reference="J_LLEG1">
	<stopErp>0.2</stopErp>
	<provideFeedback>true</provideFeedback>
  </gazebo>  
  <gazebo reference="J_LLEG2">
	<stopErp>0.2</stopErp>
	<provideFeedback>true</provideFeedback>
  </gazebo>  
  <gazebo reference="J_LLEG3">
	<stopErp>0.2</stopErp>
	<provideFeedback>true</provideFeedback>
  </gazebo>  
  <gazebo reference="J_LLEG4">
	<stopErp>0.2</stopErp>
	<provideFeedback>true</provideFeedback>
  </gazebo>  
  <gazebo reference="J_RLEG0">
	<stopErp>0.2</stopErp>
	<provideFeedback>true</provideFeedback>
  </gazebo>  
  <gazebo reference="J_RLEG1">
	<stopErp>0.2</stopErp>
	<provideFeedback>true</provideFeedback>
  </gazebo>  
  <gazebo reference="J_RLEG2">
	<stopErp>0.2</stopErp>
	<provideFeedback>true</provideFeedback>
  </gazebo>  
  <gazebo reference="J_RLEG3">
	<stopErp>0.2</stopErp>
	<provideFeedback>true</provideFeedback>
  </gazebo>  
  <gazebo reference="J_RLEG4">
	<stopErp>0.2</stopErp>
	<provideFeedback>true</provideFeedback>
  </gazebo> 
  <gazebo reference="J_RARM2">
	<stopErp>0.2</stopErp>
	<provideFeedback>true</provideFeedback>
  </gazebo> 
  <gazebo reference="J_LFOOT">
	<stopErp>0.2</stopErp>
	<provideFeedback>true</provideFeedback>
  </gazebo>  
  <gazebo reference="J_RFOOT">
	<stopErp>0.2</stopErp>
	<provideFeedback>true</provideFeedback>
  </gazebo>  
  <gazebo reference="J_RFOOT_SENSOR0">
	<provideFeedback>true</provideFeedback>
  </gazebo>  
  <gazebo reference="J_RFOOT_SENSOR1">
	<provideFeedback>true</provideFeedback>
  </gazebo>
  <gazebo reference="J_RFOOT_SENSOR2">
	<provideFeedback>true</provideFeedback>
  </gazebo>
  <gazebo reference="J_RFOOT_SENSOR3">
	<provideFeedback>true</provideFeedback>
  </gazebo>
  <gazebo reference="J_LFOOT_SENSOR0">
	<provideFeedback>true</provideFeedback>
  </gazebo>  
  <gazebo reference="J_LFOOT_SENSOR1">
	<provideFeedback>true</provideFeedback>
  </gazebo>
  <gazebo reference="J_LFOOT_SENSOR2">
	<provideFeedback>true</provideFeedback>
  </gazebo>
  <gazebo reference="J_LFOOT_SENSOR3">
	<provideFeedback>true</provideFeedback>
  </gazebo>
  <gazebo reference="TRUNK">
    <mu1>1.0</mu1>
    <mu2>1.0</mu2>
    <kp>1220000.0</kp>
    <kd>1.0</kd> <!---->
  </gazebo>
  <gazebo reference="RFOOT">
    <mu1>1.0</mu1>
    <mu2>1.0</mu2>
    <kp>1220000.0</kp>
    <kd>1.0</kd> <!---->
  </gazebo>
  <gazebo reference="LFOOT">
    <mu1>1.0</mu1>
    <mu2>1.0</mu2>
    <kp>1220000.0</kp>
    <kd>1.0</kd> <!---->
  </gazebo>  
<!-- FT SENSORS -->
<!--  <gazebo>
	<plugin name="ft_sensor" filename="libgazebo_ros_ft_sensor.so">
	  <updateRate>100.0</updateRate>
	  <topicName>ft_sensor_head0</topicName>
	  <jointName>J_HEAD0</jointName>
	</plugin>
  </gazebo>
  <gazebo>
	<plugin name="ft_sensor" filename="libgazebo_ros_ft_sensor.so">
	  <updateRate>100.0</updateRate>
	  <topicName>ft_sensor_head1</topicName>
	  <jointName>J_HEAD1</jointName>
	</plugin>
  </gazebo>

  <gazebo>
	<plugin name="ft_sensor" filename="libgazebo_ros_ft_sensor.so">
	  <updateRate>100.0</updateRate>
	  <topicName>ft_sensor_larm0</topicName>
	  <jointName>J_LARM0</jointName>
	</plugin>
  </gazebo>
  <gazebo>
	<plugin name="ft_sensor" filename="libgazebo_ros_ft_sensor.so">
	  <updateRate>100.0</updateRate>
	  <topicName>ft_sensor_larm1</topicName>
	  <jointName>J_LARM1</jointName>
	</plugin>
  </gazebo>
  <gazebo>
	<plugin name="ft_sensor" filename="libgazebo_ros_ft_sensor.so">
	  <updateRate>100.0</updateRate>
	  <topicName>ft_sensor_larm2</topicName>
	  <jointName>J_LARM2</jointName>
	</plugin>
  </gazebo>
  
  
    <gazebo>
	<plugin name="ft_sensor" filename="libgazebo_ros_ft_sensor.so">
	  <updateRate>100.0</updateRate>
	  <topicName>ft_sensor_rarm0</topicName>
	  <jointName>J_RARM0</jointName>
	</plugin>
  </gazebo>
  <gazebo>
	<plugin name="ft_sensor" filename="libgazebo_ros_ft_sensor.so">
	  <updateRate>100.0</updateRate>
	  <topicName>ft_sensor_rarm1</topicName>
	  <jointName>J_RARM1</jointName>
	</plugin>
  </gazebo>
  <gazebo>
	<plugin name="ft_sensor" filename="libgazebo_ros_ft_sensor.so">
	  <updateRate>100.0</updateRate>
	  <topicName>ft_sensor_rarm2</topicName>
	  <jointName>J_RARM2</jointName>
	</plugin>
  </gazebo>
  
  
  
  <gazebo>
	<plugin name="ft_sensor" filename="libgazebo_ros_ft_sensor.so">
	  <updateRate>100.0</updateRate>
	  <topicName>ft_sensor_lleg0</topicName>
	  <jointName>J_LLEG0</jointName>
	</plugin>
  </gazebo>
    <gazebo>
	<plugin name="ft_sensor" filename="libgazebo_ros_ft_sensor.so">
	  <updateRate>100.0</updateRate>
	  <topicName>ft_sensor_lleg1</topicName>
	  <jointName>J_LLEG1</jointName>
	</plugin>
  </gazebo>
    <gazebo>
	<plugin name="ft_sensor" filename="libgazebo_ros_ft_sensor.so">
	  <updateRate>100.0</updateRate>
	  <topicName>ft_sensor_lleg2</topicName>
	  <jointName>J_LLEG2</jointName>
	</plugin>
  </gazebo>
    <gazebo>
	<plugin name="ft_sensor" filename="libgazebo_ros_ft_sensor.so">
	  <updateRate>100.0</updateRate>
	  <topicName>ft_sensor_lleg3</topicName>
	  <jointName>J_LLEG3</jointName>
	</plugin>
  </gazebo>
    <gazebo>
	<plugin name="ft_sensor" filename="libgazebo_ros_ft_sensor.so">
	  <updateRate>100.0</updateRate>
	  <topicName>ft_sensor_lleg4</topicName>
	  <jointName>J_LLEG4</jointName>
	</plugin>
  </gazebo>
    <gazebo>
	<plugin name="ft_sensor" filename="libgazebo_ros_ft_sensor.so">
	  <updateRate>100.0</updateRate>
	  <topicName>ft_sensor_lfoot</topicName>
	  <jointName>J_LFOOT</jointName>
	</plugin>
  </gazebo>
  
    <gazebo>
	<plugin name="ft_sensor" filename="libgazebo_ros_ft_sensor.so">
	  <updateRate>100.0</updateRate>
	  <topicName>ft_sensor_rleg0</topicName>
	  <jointName>J_RLEG0</jointName>
	</plugin>
  </gazebo>
    <gazebo>
	<plugin name="ft_sensor" filename="libgazebo_ros_ft_sensor.so">
	  <updateRate>100.0</updateRate>
	  <topicName>ft_sensor_rleg1</topicName>
	  <jointName>J_RLEG1</jointName>
	</plugin>
  </gazebo>
    <gazebo>
	<plugin name="ft_sensor" filename="libgazebo_ros_ft_sensor.so">
	  <updateRate>100.0</updateRate>
	  <topicName>ft_sensor_rleg2</topicName>
	  <jointName>J_RLEG2</jointName>
	</plugin>
  </gazebo>
    <gazebo>
	<plugin name="ft_sensor" filename="libgazebo_ros_ft_sensor.so">
	  <updateRate>100.0</updateRate>
	  <topicName>ft_sensor_rleg3</topicName>
	  <jointName>J_RLEG3</jointName>
	</plugin>
  </gazebo>
    <gazebo>
	<plugin name="ft_sensor" filename="libgazebo_ros_ft_sensor.so">
	  <updateRate>100.0</updateRate>
	  <topicName>ft_sensor_rleg4</topicName>
	  <jointName>J_RLEG4</jointName>
	</plugin>
  </gazebo>
    <gazebo>
	<plugin name="ft_sensor" filename="libgazebo_ros_ft_sensor.so">
	  <updateRate>100.0</updateRate>
	  <topicName>ft_sensor_rfoot</topicName>
	  <jointName>J_RFOOT</jointName>
	</plugin>
  </gazebo>
  
  -->
  
  <gazebo>
	<plugin name="ft_sensor" filename="libgazebo_ros_ft_sensor.so">
	  <updateRate>500.0</updateRate>
	  <topicName>ft_sensor_rSensor0</topicName>
	  <jointName>J_RFOOT_SENSOR0</jointName>
	</plugin>
	<plugin name="ft_sensor" filename="libgazebo_ros_ft_sensor.so">
	  <updateRate>500.0</updateRate>
	  <topicName>ft_sensor_rSensor1</topicName>
	  <jointName>J_RFOOT_SENSOR1</jointName>
	</plugin>
	<plugin name="ft_sensor" filename="libgazebo_ros_ft_sensor.so">
	  <updateRate>500.0</updateRate>
	  <topicName>ft_sensor_rSensor2</topicName>
	  <jointName>J_RFOOT_SENSOR2</jointName>
	</plugin>
	<plugin name="ft_sensor" filename="libgazebo_ros_ft_sensor.so">
	  <updateRate>500.0</updateRate>
	  <topicName>ft_sensor_rSensor3</topicName>
	  <jointName>J_RFOOT_SENSOR3</jointName>
	</plugin>
	<plugin name="ft_sensor" filename="libgazebo_ros_ft_sensor.so">
	  <updateRate>500.0</updateRate>
	  <topicName>ft_sensor_lSensor0</topicName>
	  <jointName>J_LFOOT_SENSOR0</jointName>
	</plugin>
	<plugin name="ft_sensor" filename="libgazebo_ros_ft_sensor.so">
	  <updateRate>500.0</updateRate>
	  <topicName>ft_sensor_lSensor1</topicName>
	  <jointName>J_LFOOT_SENSOR1</jointName>
	</plugin>
	<plugin name="ft_sensor" filename="libgazebo_ros_ft_sensor.so">
	  <updateRate>500.0</updateRate>
	  <topicName>ft_sensor_lSensor2</topicName>
	  <jointName>J_LFOOT_SENSOR2</jointName>
	</plugin>
	<plugin name="ft_sensor" filename="libgazebo_ros_ft_sensor.so">
	  <updateRate>500.0</updateRate>
	  <topicName>ft_sensor_lSensor3</topicName>
	  <jointName>J_LFOOT_SENSOR3</jointName>
	</plugin>
	<plugin name="ft_sensor" filename="libgazebo_ros_ft_sensor.so">
	  <updateRate>125.0</updateRate>
	  <topicName>ft_sensor_rleg3</topicName>
	  <jointName>J_RLEG3</jointName>
	</plugin>
	<plugin name="ft_sensor" filename="libgazebo_ros_ft_sensor.so">
	  <updateRate>125.0</updateRate>
	  <topicName>ft_sensor_lleg3</topicName>
	  <jointName>J_LLEG3</jointName>
	</plugin>
	
	<plugin name="ft_sensor" filename="libgazebo_ros_ft_sensor.so">
	  <updateRate>125.0</updateRate>
	  <topicName>ft_sensor_rleg4</topicName>
	  <jointName>J_RLEG4</jointName>
	</plugin>
	<plugin name="ft_sensor" filename="libgazebo_ros_ft_sensor.so">
	  <updateRate>125.0</updateRate>
	  <topicName>ft_sensor_lleg4</topicName>
	  <jointName>J_LLEG4</jointName>
	</plugin>
	
		<plugin name="ft_sensor" filename="libgazebo_ros_ft_sensor.so">
	  <updateRate>125.0</updateRate>
	  <topicName>ft_sensor_rfoot</topicName>
	  <jointName>J_RFOOT</jointName>
	</plugin>
	<plugin name="ft_sensor" filename="libgazebo_ros_ft_sensor.so">
	  <updateRate>125.0</updateRate>
	  <topicName>ft_sensor_lfoot</topicName>
	  <jointName>J_LFOOT</jointName>
	</plugin>
  </gazebo>
  

  <link name="world">  </link>
  
  <link name="imu_link">
    <collision>
      <origin xyz="0 0 0" rpy="0 0 0"/>
      <geometry>
    <box size="0.01 0.01 0.01"/>
      </geometry>
    </collision>

    <visual>
      <origin xyz="0 0 0" rpy="0 0 0"/>
      <geometry>
    <box size="0.01 0.01 0.01"/>
      </geometry>

    </visual>

    <inertial>
      <mass value="1e-3" />
      <origin xyz="0 0 0" rpy="0 0 0"/>
      <inertia ixx="1e-3" ixy="0" ixz="0" iyy="1e-3" iyz="0" izz="1e-3" />
    </inertial>
  </link>
  <joint name="imu_joint" type="fixed">
    <axis xyz="-1 0 0" />
    <origin xyz="0 0 0" rpy="0 0 0"/>
    <parent link="TRUNK"/>
    <child link="imu_link"/>
  </joint>
  
  
   <!-- Camera -->
  <link name="camera_link">
    <visual>
      <origin xyz="0 0 0" rpy="0 0 0"/>
      <geometry>
    <box size="0.01 0.01 0.01"/>
      </geometry>

    </visual>

    <inertial>
      <mass value="1e-3" />
      <origin xyz="0 0 0" rpy="0 0 0"/>
      <inertia ixx="1e-3" ixy="0" ixz="0" iyy="1e-3" iyz="0" izz="1e-3" />
    </inertial>
  </link>
  
  <joint name="camera_joint" type="fixed">
    <axis xyz="0 0 1" />
    <origin xyz="0.02 0.055 0.00" rpy="-1.5707 0 0"/>
    <parent link="HEAD1"/>
    <child link="camera_link"/>
  </joint>

  
  
  
  <link
    name="TRUNK">
    <inertial>
      <origin
        xyz="-0.000142944293532541 -0.0159940135836359 0.119253638413231"
        rpy="0 0 0" />
      <mass
        value="1.4778155091901" />
      <inertia
        ixx="0.0125398154437975"
        ixy="0"
        ixz="0"
        iyy="0.016695640033345"
        iyz="0.000776177026664091"
        izz="0.01567882258573842" />
    </inertial>
    <visual>
      <origin
        xyz="0 0 0"
        rpy="0 0 0" />
      <geometry>
        <mesh
          filename="package://sakura_description/meshes/TRUNK.STL" />
      </geometry>
      <material
        name="">
        <color
          rgba="0.752941176470588 0.752941176470588 0.752941176470588 1" />
      </material>
    </visual>
  </link>
  <joint name="fixed" type="floating">
    <parent link="world"/>
    <child link="TRUNK"/>
    <origin xyz="0 0 0.50" rpy="0 0 0"/>
  </joint>
  <link
    name="HEAD0">
    <inertial>
      <origin
        xyz="0 -0.00045169 0.0273"
        rpy="0 0 0" />
      <mass
        value="0.072495" />
      <inertia ixx="1e-3" ixy="0" ixz="0" iyy="1e-3" iyz="0" izz="1e-3" />
    </inertial>
    <visual>
      <origin
        xyz="0 0 0"
        rpy="0 0 0" />
      <geometry>
        <mesh
          filename="package://sakura_description/meshes/HEAD0.STL" />
      </geometry>
      <material
        name="">
        <color
          rgba="0.79216 0.81961 0.93333 1" />
      </material>
    </visual>
  </link>
  <link
    name="HEAD1">
    <inertial>
      <origin
        xyz="0.000492167176094648 0.0499545659310894 0"
        rpy="0 0 0" />
      <mass
        value="0.160467558648652" />
      <inertia ixx="1e-3" ixy="0" ixz="0" iyy="1e-3" iyz="0" izz="1e-3" />
    </inertial>
    <visual>
      <origin
        xyz="0 0 0"
        rpy="0 0 0" />
      <geometry>
        <mesh
          filename="package://sakura_description/meshes/HEAD1.STL" />
      </geometry>
      <material
        name="">
        <color
          rgba="0.792156862745098 0.819607843137255 0.933333333333333 1" />
      </material>
    </visual>
  </link>

  
  <joint
    name="J_HEAD0"
    type="continuous">
    <origin
      xyz="0 0.002 0.2785"
      rpy="0 0 -1.5708" />
    <parent
      link="TRUNK" />
    <child
      link="HEAD0" />
    <axis
      xyz="0 0 1" />
    <limit
      effort="10"
      velocity="8.58" />
    <dynamics 
	  damping="0.7"
	  friction="0.5"/>
  </joint>
  
  <joint
    name="J_HEAD1"
    type="continuous">
    <origin
      xyz="0 -0.0005 0.0425"
      rpy="1.5708 0 3.1416" />
    <parent
      link="HEAD0" />
    <child
      link="HEAD1" />
    <axis
      xyz="0 0 -1" />
    <limit
      effort="10"
      velocity="8.58" />
    <dynamics 
	  damping="0.7"
	  friction="0.5"/>
  </joint>
  
  <link
    name="LARM0">
    <inertial>
      <origin
        xyz="0 0 0.0103025666414173"
        rpy="0 0 0" />
      <mass
        value="0.0066175226097181" />
      <inertia
        ixx="1.E-03"
        ixy="0"
        ixz="0"
        iyy="1.E-03"
        iyz="0"
        izz="1.E-03" />
    </inertial>
    <visual>
      <origin
        xyz="0 0 0"
        rpy="0 0 0" />
      <geometry>
        <mesh
          filename="package://sakura_description/meshes/LARM0.STL" />
      </geometry>
      <material
        name="">
        <color
          rgba="0.792156862745098 0.819607843137255 0.933333333333333 1" />
      </material>
    </visual>
  </link>
  <joint
    name="J_LARM0"
    type="continuous">
    <origin
      xyz="-0.094 -0.0125 0.237"
      rpy="1.5708 3.14159 -1.5708" />
    <parent
      link="TRUNK" />
    <child
      link="LARM0" />
    <axis
      xyz="0 0 1" />
    <limit
      effort="10"
      velocity="8.58" />
    <dynamics 
     damping="0.7"
     friction="0.5"/>
  </joint>
  <link
    name="LARM1">
    <inertial>
      <origin
        xyz="-0.000203905909046856 -0.0358166170046635 -0.030724518771744"
        rpy="0 0 0" />
      <mass
        value="0.386889741732442" />
      <inertia
        ixx="0.001319462933467775"
        ixy="0"
        ixz="0"
        iyy="0.001"
        iyz="0"
        izz="0.001386423060557297" />
    </inertial>
    <visual>
      <origin
        xyz="0 0 0"
        rpy="0 0 0" />
      <geometry>
        <mesh
          filename="package://sakura_description/meshes/LARM1.STL" />
      </geometry>
      <material
        name="">
        <color
          rgba="0.898039215686275 0.92156862745098 0.929411764705882 1" />
      </material>
    </visual>
  </link>
  <joint
    name="J_LARM1"
    type="continuous">
    <origin
      xyz="-0.0308 0 0.036"
      rpy="3.1416 1.5708 0" />
    <parent
      link="LARM0" />
    <child
      link="LARM1" />
    <axis
      xyz="0 0 -1" />
    <limit
      effort="10"
      velocity="8.58" />
        <dynamics 
     damping="0.7"
     friction="0.5"/>
  </joint>
  <link
    name="LARM2">
    <inertial>
      <origin
        xyz="-0.000946892853796732 -0.0604743903550126 -0.030549305382329"
        rpy="0 0 0" />
      <mass
        value="0.417770884687889" />
      <inertia
        ixx="0.00130365609096481"
        ixy="0"
        ixz="0"
        iyy="0.001"
        iyz="0"
        izz="0.00130522583526536" />
    </inertial>
    <visual>
      <origin
        xyz="0 0 0"
        rpy="0 0 0" />
      <geometry>
        <mesh
          filename="package://sakura_description/meshes/LARM2.STL" />
      </geometry>
      <material
        name="">
        <color
          rgba="0.898039215686275 0.92156862745098 0.929411764705882 1" />
      </material>
    </visual>
  </link>
  <joint
    name="J_LARM2"
    type="continuous">
    <origin
      xyz="0.0307 -0.1235 -0.0308"
      rpy="0 1.5708 0" />
    <parent
      link="LARM1" />
    <child
      link="LARM2" />
    <axis
      xyz="0 0 -1" />
    <limit
      effort="10"
      velocity="8.58" />
        <dynamics 
     damping="0.7"
     friction="0.5"/>
  </joint>
  <link
    name="RARM0">
    <inertial>
      <origin
        xyz="0 0 0.0103025666414173"
        rpy="0 0 0" />
      <mass
        value="0.00661752260971814" />
      <inertia
        ixx="1.E-03"
        ixy="0"
        ixz="0"
        iyy="1.E-03"
        iyz="0"
        izz="1.E-03" />
    </inertial>
    <visual>
      <origin
        xyz="0 0 0"
        rpy="0 0 0" />
      <geometry>
        <mesh
          filename="package://sakura_description/meshes/RARM0.STL" />
      </geometry>
      <material
        name="">
        <color
          rgba="0.792156862745098 0.819607843137255 0.933333333333333 1" />
      </material>
    </visual>
  </link>
  <joint
    name="J_RARM0"
    type="continuous">
    <origin
      xyz="0.094 -0.0125 0.237"
      rpy="-1.5708 0 -1.5708" />
    <parent
      link="TRUNK" />
    <child
      link="RARM0" />
    <axis
      xyz="0 0 1" />
    <limit
      effort="10"
      velocity="8.58" />
        <dynamics 
     damping="0.7"
     friction="0.5"/>
  </joint>
  <link
    name="RARM1">
    <inertial>
      <origin
        xyz="-0.00020391 -0.035817 -0.030725"
        rpy="0 0 0" />
      <mass
        value="0.38689" />
      <inertia
        ixx="0.00131946"
        ixy="0"
        ixz="0"
        iyy="0.001"
        iyz="0"
        izz="0.00138642" />
    </inertial>
    <visual>
      <origin
        xyz="0 0 0"
        rpy="0 0 0" />
      <geometry>
        <mesh
          filename="package://sakura_description/meshes/RARM1.STL" />
      </geometry>
      <material
        name="">
        <color
          rgba="0.89804 0.92157 0.92941 1" />
      </material>
    </visual>
  </link>
  <joint
    name="J_RARM1"
    type="continuous">
    <origin
      xyz="-0.0308 0 0.036"
      rpy="3.1416 1.5708 0" />
    <parent
      link="RARM0" />
    <child
      link="RARM1" />
    <axis
      xyz="0 0 1" />
    <limit
      effort="10"
      velocity="8.58" />
        <dynamics 
     damping="0.7"
     friction="0.5"/>
  </joint>
  <link
    name="RARM2">
    <inertial>
      <origin
        xyz="-0.000946892853796774 -0.0604743903550127 -0.0305493053823289"
        rpy="0 0 0" />
      <mass
        value="0.417770884687889" />
      <inertia
        ixx="0.00130365609096481"
        ixy="0"
        ixz="0"
        iyy="0.001"
        iyz="0"
        izz="0.00130522583526536" />
    </inertial>
    <visual>
      <origin
        xyz="0 0 0"
        rpy="0 0 0" />
      <geometry>
        <mesh
          filename="package://sakura_description/meshes/RARM2.STL" />
      </geometry>
      <material
        name="">
        <color
          rgba="0.898039215686275 0.92156862745098 0.929411764705882 1" />
      </material>
    </visual>
  </link>
  <joint
    name="J_RARM2"
    type="continuous">
    <origin
      xyz="0.0307 -0.1235 -0.0308"
      rpy="0 1.5708 0" />
    <parent
      link="RARM1" />
    <child
      link="RARM2" />
    <axis
      xyz="0 0 -1" />
    <limit
      effort="10"
      velocity="8.58" />
        <dynamics 
     damping="0.7"
     friction="0.5"/>
  </joint>
  <link
    name="LLEG0">
    <inertial>
      <origin
        xyz="0 0 0.012339611662812"
        rpy="0 0 0" />
      <mass
        value="0.137487098095279" />
      <inertia
        ixx="0.001"
        ixy="0"
        ixz="0"
        iyy="0.001"
        iyz="0"
        izz="0.001" />
    </inertial>
    <visual>
      <origin
        xyz="0 0 0"
        rpy="0 0 0" />
      <geometry>
        <mesh
          filename="package://sakura_description/meshes/LLEG0.STL" />
      </geometry>
      <material
        name="">
        <color
          rgba="0.650980392156863 0.619607843137255 0.588235294117647 1" />
      </material>
    </visual>
  </link>
  <joint
    name="J_LLEG0"
    type="continuous">
    <origin
      xyz="-0.057 -0.0325 -0.005"
      rpy="-3.14159265358979 0 -1.5707963267949" />
    <parent
      link="TRUNK" />
    <child
      link="LLEG0" />
    <axis
      xyz="0 0 1" />
    <limit
      effort="10"
      velocity="8.58" />
        <dynamics 
     damping="0.7"
     friction="0.5"/>
  </joint>
  <link
    name="LLEG1">
    <inertial>
      <origin
        xyz="0 -0.014933566350856 -0.0542307430726147"
        rpy="0 0 0" />
      <mass
        value="0.484317524341268" />
      <inertia
        ixx="0.001258532465487086"
        ixy="0"
        ixz="0"
        iyy="0.001256538006237082"
        iyz="0"
        izz="0.001" />
    </inertial>
    <visual>
      <origin
        xyz="0 0 0"
        rpy="0 0 0" />
      <geometry>
        <mesh
          filename="package://sakura_description/meshes/LLEG1.STL" />
      </geometry>
      <material
        name="">
        <color
          rgba="0.752941176470588 0.752941176470588 0.752941176470588 1" />
      </material>
    </visual>
  </link>
  <joint
    name="J_LLEG1"
    type="continuous">
    <origin
      xyz="0.056 0 0.036"
      rpy="-1.5707963267949 0 -1.5707963267949" />
    <parent
      link="LLEG0" />
    <child
      link="LLEG1" />
    <axis
      xyz="0 0 -1" />
    <limit
      effort="10"
      velocity="8.58" />
        <dynamics 
     damping="0.7"
     friction="0.5"/>
  </joint>
  <link
    name="LLEG2">
    <inertial>
      <origin
        xyz="0.0896135033902749 -0.121669815792639 -0.0285739776731877"
        rpy="0 0 0" />
      <mass
        value="0.429581814867276" />
      <inertia
        ixx="0.001739443276879588"
        ixy="0.000469298592224479"
        ixz="0"
        iyy="0.00145781924000273"
        iyz="0"
        izz="0.00100793675092908" />
    </inertial>
    <visual>
      <origin
        xyz="0 0 0"
        rpy="0 0 0" />
      <geometry>
        <mesh
          filename="package://sakura_description/meshes/LLEG2.STL" />
      </geometry>
      <material
        name="">
        <color
          rgba="0.752941176470588 0.752941176470588 0.752941176470588 1" />
      </material>
    </visual>
  </link>
  <joint
    name="J_LLEG2"
    type="continuous">
    <origin
      xyz="0.0289999999999999 0 -0.0750000000000234"
      rpy="-1.5707963267949 0.78539816339745 -1.5707963267949" />
    <parent
      link="LLEG1" />
    <child
      link="LLEG2" />
    <axis
      xyz="0 0 1" />
    <limit
      effort="10"
      velocity="8.58" />
        <dynamics 
     damping="0.7"
     friction="0.5"/>
  </joint>
  <link
    name="LLEG3">
    <inertial>
      <origin
        xyz="0.0938607247050214 0.021121469241447 -0.0266864244548486"
        rpy="0 0 0" />
      <mass
        value="0.253457988874213" />
      <inertia
        ixx="0.001157893827081503"
        ixy="0"
        ixz="0"
        iyy="0.001215254509125973"
        iyz="0"
        izz="0.001" />
    </inertial>
    <visual>
      <origin
        xyz="0 0 0"
        rpy="0 0 0" />
      <geometry>
        <mesh
          filename="package://sakura_description/meshes/LLEG3.STL" />
      </geometry>
      <material
        name="">
        <color
          rgba="0.752941176470588 0.752941176470588 0.752941176470588 1" />
      </material>
    </visual>
  </link>
  <joint
    name="J_LLEG3"
    type="continuous">
    <origin
      xyz="0.112429978208667 -0.169643181644254 0.00160000000000024"
      rpy="-0.0320557226319531 0.0283578707512148 -1.01721646459287" />
    <parent
      link="LLEG2" />
    <child
      link="LLEG3" />
    <axis
      xyz="-0.0283540701513945 -0.0320373469653184 0.999084408398647" />
    <limit
      effort="10"
      velocity="8.58" />
        <dynamics 
     damping="0.7"
     friction="0.5"/>  
  </joint>
  <link
    name="LLEG4">
    <inertial>
      <origin
        xyz="0.0207692569273853 -0.0149335663508559 -0.0309509783436903"
        rpy="0 0 0" />
      <mass
        value="0.484317524341267" />
      <inertia
        ixx="0.001"
        ixy="0"
        ixz="0"
        iyy="0.001256538006237082"
        iyz="0"
        izz="0.001258532465487085" />
    </inertial>
    <visual>
      <origin
        xyz="0 0 0"
        rpy="0 0 0" />
      <geometry>
        <mesh
          filename="package://sakura_description/meshes/LLEG4.STL" />
      </geometry>
      <material
        name="">
        <color
          rgba="0.752941176470588 0.752941176470588 0.752941176470588 1" />
      </material>
    </visual>
  </link>
  <joint
    name="J_LLEG4"
    type="continuous">
    <origin
      xyz="0.19759 0.040682 0.007913"
      rpy="0.034963 0.024684 -1.339" />
    <parent
      link="LLEG3" />
    <child
      link="LLEG4" />
    <axis
      xyz="0 0 -1" />
    <limit
      effort="10"
      velocity="8.58" />
        <dynamics 
     damping="0.7"
     friction="0.5"/>
  </joint>
  <link
    name="LFOOT">
    <inertial>
      <origin
        xyz="-0.00984398078216434 0.033081446163245 0.0742424926896279"
        rpy="0 0 0" />
      <mass
        value="0.474832547151362" />
      <inertia
        ixx="0.001"
        ixy="0"
        ixz="0"
        iyy="0.001"
        iyz="0"
        izz="0.001" />
    </inertial>
    <visual>
      <origin
        xyz="0 0 0"
        rpy="0 0 0" />
      <geometry>
        <mesh
          filename="package://sakura_description/meshes/LFOOT.STL" />
      </geometry>
      <material
        name="">
        <color
          rgba="0.752941176470588 0.752941176470588 0.752941176470588 1" />
      </material>
    </visual>
    <collision>
      <origin
        xyz="-0.01 0.021 0.078"
        rpy="0 0 0" />
        <geometry>
          <box size="0.13 0.03 0.208"/>
        </geometry>
    </collision>
  </link>
  <joint
    name="J_LFOOT"
    type="continuous">
    <origin
      xyz="0.072 0 -0.031"
      rpy="0 -1.5708 0" />
    <parent
      link="LLEG4" />
    <child
      link="LFOOT" />
    <axis
      xyz="0 0 -1" />
    <limit
      effort="10"
      velocity="8.58" />
        <dynamics 
     damping="0.7"
     friction="0.5"/>
  </joint>
  <link
    name="RLEG0">
    <inertial>
      <origin
        xyz="0 0 0.012339611662812"
        rpy="0 0 0" />
      <mass
        value="0.137487098095279" />
      <inertia
        ixx="0.001"
        ixy="0"
        ixz="0"
        iyy="0.001"
        iyz="0"
        izz="0.001" />
    </inertial>
    <visual>
      <origin
        xyz="0 0 0"
        rpy="0 0 0" />
      <geometry>
        <mesh
          filename="package://sakura_description/meshes/RLEG0.STL" />
      </geometry>
      <material
        name="">
        <color
          rgba="0.650980392156863 0.619607843137255 0.588235294117647 1" />
      </material>
    </visual>
  </link>
  <joint
    name="J_RLEG0"
    type="continuous">
    <origin
      xyz="0.057 -0.0325 -0.005"
      rpy="-3.14159265358979 0 -1.5707963267949" />
    <parent
      link="TRUNK" />
    <child
      link="RLEG0" />
    <axis
      xyz="0 0 1" />
    <limit
      effort="10"
      velocity="8.58" />
        <dynamics 
     damping="0.7"
     friction="0.5"/>
  </joint>
  <link
    name="RLEG1">
    <inertial>
      <origin
        xyz="0 -0.014934 -0.054231"
        rpy="0 0 0" />
      <mass
        value="0.48432" />
      <inertia
        ixx="0.00125853"
        ixy="0"
        ixz="0"
        iyy="0.00125654"
        iyz="0"
        izz="0.001" />
    </inertial>
    <visual>
      <origin
        xyz="0 0 0"
        rpy="0 0 0" />
      <geometry>
        <mesh
          filename="package://sakura_description/meshes/RLEG1.STL" />
      </geometry>
      <material
        name="">
        <color
          rgba="0.75294 0.75294 0.75294 1" />
      </material>
    </visual>
  </link>
  <joint
    name="J_RLEG1"
    type="continuous">
    <origin
      xyz="0.056 0 0.036"
      rpy="-1.5707963267949 0 -1.5707963267949" />
    <parent
      link="RLEG0" />
    <child
      link="RLEG1" />
    <axis
      xyz="0 0 -1" />
    <limit
      effort="10"
      velocity="8.58" />
        <dynamics 
     damping="0.7"
     friction="0.5"/>
  </joint>
  <link
    name="RLEG2">
    <inertial>
      <origin
        xyz="0.089613503390275 -0.121669815792639 -0.0285739776731877"
        rpy="0 0 0" />
      <mass
        value="0.429581814867276" />
      <inertia
        ixx="0.001739443276879589"
        ixy="0.00046929859222448"
        ixz="0"
        iyy="0.001457819240002731"
        iyz="0"
        izz="0.00100793675092908" />
    </inertial>
    <visual>
      <origin
        xyz="0 0 0"
        rpy="0 0 0" />
      <geometry>
        <mesh
          filename="package://sakura_description/meshes/RLEG2.STL" />
      </geometry>
      <material
        name="">
        <color
          rgba="0.752941176470588 0.752941176470588 0.752941176470588 1" />
      </material>
    </visual>
  </link>
  <joint
    name="J_RLEG2"
    type="continuous">
    <origin
      xyz="0.0290000000000001 0 -0.075"
      rpy="-1.5707963267949 0.78539816339745 -1.5707963267949" />
    <parent
      link="RLEG1" />
    <child
      link="RLEG2" />
    <axis
      xyz="0 0 -1" />
    <limit
      effort="10"
      velocity="8.58" />
        <dynamics 
     damping="0.7"
     friction="0.5"/>
  </joint>
  <link
    name="RLEG3">
    <inertial>
      <origin
        xyz="0.093861 0.021121 -0.026686"
        rpy="0 0 0" />
      <mass
        value="0.25346" />
      <inertia
        ixx="0.00115789"
        ixy="0"
        ixz="0"
        iyy="0.00121525"
        iyz="0"
        izz="0.001" />
    </inertial>
    <visual>
      <origin
        xyz="0 0 0"
        rpy="0 0 0" />
      <geometry>
        <mesh
          filename="package://sakura_description/meshes/RLEG3.STL" />
      </geometry>
      <material
        name="">
        <color
          rgba="0.75294 0.75294 0.75294 1" />
      </material>
    </visual>
  </link>
  <joint
    name="J_RLEG3"
    type="continuous">
    <origin
      xyz="0.112429978208668 -0.169643181644253 0.00160000000000014"
      rpy="-0.0320557226319534 0.0283578707512146 -1.01721646459286" />
    <parent
      link="RLEG2" />
    <child
      link="RLEG3" />
    <axis
      xyz="0.0283540701513948 0.0320373469653193 -0.999084408398647" />
    <limit
      effort="10"
      velocity="8.58" />
        <dynamics 
     damping="0.7"
     friction="0.5"/>
  </joint>
  <link
    name="RLEG4">
    <inertial>
      <origin
        xyz="0.0207692569273853 -0.014933566350856 -0.0309509783436903"
        rpy="0 0 0" />
      <mass
        value="0.484317524341268" />
      <inertia
        ixx="0.001"
        ixy="0"
        ixz="0"
        iyy="0.001256538006237082"
        iyz="0"
        izz="0.001258532465487085" />
    </inertial>
    <visual>
      <origin
        xyz="0 0 0"
        rpy="0 0 0" />
      <geometry>
        <mesh
          filename="package://sakura_description/meshes/RLEG4.STL" />
      </geometry>
      <material
        name="">
        <color
          rgba="0.752941176470588 0.752941176470588 0.752941176470588 1" />
      </material>
    </visual>
  </link>
  <joint
    name="J_RLEG4"
    type="continuous">
    <origin
      xyz="0.19759 0.040682 0.007913"
      rpy="0.034963 0.024684 -1.339" />
    <parent
      link="RLEG3" />
    <child
      link="RLEG4" />
    <axis
      xyz="0 0 1" />
    <limit
      effort="10"
      velocity="8.58" />
        <dynamics 
     damping="0.7"
     friction="0.5"/>
  </joint>
  <link
    name="RFOOT">
    <inertial>
      <origin
        xyz="0.009844 0.033081 0.074242"
        rpy="0 0 0" />
      <mass
        value="0.47483" />
      <inertia
        ixx="0.001"
        ixy="0"
        ixz="0"
        iyy="0.001"
        iyz="0"
        izz="0.001" />
    </inertial>
    <visual>
      <origin
        xyz="0 0 0"
        rpy="0 0 0" />
      <geometry>
        <mesh
          filename="package://sakura_description/meshes/RFOOT.STL" />
      </geometry>
      <material
        name="">
        <color
          rgba="0.75294 0.75294 0.75294 1" />
      </material>
    </visual>
    <collision>
      <origin
        xyz="0.01 0.021 0.078"
        rpy="0 0 0" />
        <geometry>
          <box size="0.13 0.03 0.208"/>
        </geometry>
    </collision>
  </link>
  <joint
    name="J_RFOOT"
    type="continuous">
    <origin
      xyz="0.072 0 -0.031"
      rpy="0 -1.5708 0" />
    <parent
      link="RLEG4" />
    <child
      link="RFOOT" />
    <axis
      xyz="0 0 -1" />
    <limit
      effort="10"
      velocity="8.58" />
        <dynamics 
     damping="0.7"
     friction="0.5"/>
  </joint>
  <link
    name="RFOOT_SENSOR0">
    <inertial>
      <origin
        xyz="0 0 0"
        rpy="0 0 0" />
      <mass
        value="0.01" />
      <inertia
        ixx="0.001"
        ixy="0"
        ixz="0"
        iyy="0.001"
        iyz="0"
        izz="0.001" />
    </inertial>
    <visual>
      <origin
        xyz="-0.045 0.04 -0.015"
        rpy="0 0 0" />
        <geometry>
          <box size="0.01 0.02 0.01"/>
        </geometry>
      <material
        name="">
        <color
          rgba="0.75294 0.75294 0.75294 1" />
      </material>
    </visual>
    <collision>
      <origin
        xyz="-0.045 0.04 -0.015"
        rpy="0 0 0" />
        <geometry>
          <box size="0.01 0.02 0.01"/>
        </geometry>
    </collision>
  </link>
  <joint
    name="J_RFOOT_SENSOR0"
    type="revolute">
    <origin
      xyz="0 0 0"
      rpy="0 0 0" />
    <parent
      link="RFOOT" />
    <child
      link="RFOOT_SENSOR0" />
    <axis
      xyz="0 0 1" />
    <limit upper="0" lower="0" velocity="100" effort="1"/>
  </joint>
  <link
    name="RFOOT_SENSOR1">
    <inertial>
      <origin
        xyz="0 0 0"
        rpy="0 0 0" />
      <mass
        value="0.01" />
      <inertia
        ixx="0.001"
        ixy="0"
        ixz="0"
        iyy="0.001"
        iyz="0"
        izz="0.001" />
    </inertial>
    <visual>
      <origin
        xyz="0.070 0.04 -0.015"
        rpy="0 0 0" />
        <geometry>
          <box size="0.01 0.02 0.01"/>
        </geometry>
      <material
        name="">
        <color
          rgba="0.75294 0.75294 0.75294 1" />
      </material>
    </visual>
    <collision>
      <origin
        xyz="0.070 0.04 -0.015"
        rpy="0 0 0" />
        <geometry>
          <box size="0.01 0.02 0.01"/>
        </geometry>
    </collision>
  </link>
  <joint
    name="J_RFOOT_SENSOR1"
    type="revolute">
    <origin
      xyz="0 0 0"
      rpy="0 0 0" />
    <parent
      link="RFOOT" />
    <child
      link="RFOOT_SENSOR1" />
    <axis
      xyz="0 0 1" />
    <limit upper="0" lower="0" velocity="100" effort="1"/>
  </joint>
  <link
    name="RFOOT_SENSOR2">
    <inertial>
      <origin
        xyz="0 0 0"
        rpy="0 0 0" />
      <mass
        value="0.01" />
      <inertia
        ixx="0.001"
        ixy="0"
        ixz="0"
        iyy="0.001"
        iyz="0"
        izz="0.001" />
    </inertial>
    <visual>
      <origin
        xyz="0.070 0.04 0.17"
        rpy="0 0 0" />
        <geometry>
          <box size="0.01 0.02 0.01"/>
        </geometry>
      <material
        name="">
        <color
          rgba="0.75294 0.75294 0.75294 1" />
      </material>
    </visual>
    <collision>
      <origin
        xyz="0.070 0.04 0.17"
        rpy="0 0 0" />
        <geometry>
          <box size="0.01 0.02 0.01"/>
        </geometry>
    </collision>
  </link>
  <joint
    name="J_RFOOT_SENSOR2"
    type="revolute">
    <origin
      xyz="0 0 0"
      rpy="0 0 0" />
    <parent
      link="RFOOT" />
    <child
      link="RFOOT_SENSOR2" />
    <axis
      xyz="0 0 1" />
    <limit upper="0" lower="0" velocity="100" effort="1"/>
  </joint>
  <link
    name="RFOOT_SENSOR3">
    <inertial>
      <origin
        xyz="0 0 0"
        rpy="0 0 0" />
      <mass
        value="0.01" />
      <inertia
        ixx="0.001"
        ixy="0"
        ixz="0"
        iyy="0.001"
        iyz="0"
        izz="0.001" />
    </inertial>
    <visual>
      <origin
        xyz="-0.045 0.04 0.17"
        rpy="0 0 0" />
        <geometry>
          <box size="0.01 0.02 0.01"/>
        </geometry>
      <material
        name="">
        <color
          rgba="0.75294 0.75294 0.75294 1" />
      </material>
    </visual>
    <collision>
      <origin
        xyz="-0.045 0.04 0.17"
        rpy="0 0 0" />
        <geometry>
          <box size="0.01 0.02 0.01"/>
        </geometry>
    </collision>
  </link>
  <joint
    name="J_RFOOT_SENSOR3"
    type="revolute">
    <origin
      xyz="0 0 0"
      rpy="0 0 0" />
    <parent
      link="RFOOT" />
    <child
      link="RFOOT_SENSOR3" />
    <axis
      xyz="0 0 1" />
    <limit upper="0" lower="0" velocity="100" effort="1"/>
  </joint>
  <link
    name="LFOOT_SENSOR0">
    <inertial>
      <origin
        xyz="0 0 0"
        rpy="0 0 0" />
      <mass
        value="0.01" />
      <inertia
        ixx="0.001"
        ixy="0"
        ixz="0"
        iyy="0.001"
        iyz="0"
        izz="0.001" />
    </inertial>
    <visual>
      <origin
        xyz="-0.065 0.04 -0.015"
        rpy="0 0 0" />
        <geometry>
          <box size="0.01 0.02 0.01"/>
        </geometry>
      <material
        name="">
        <color
          rgba="0.75294 0.75294 0.75294 1" />
      </material>
    </visual>
    <collision>
      <origin
        xyz="-0.065 0.04 -0.015"
        rpy="0 0 0" />
        <geometry>
          <box size="0.01 0.02 0.01"/>
        </geometry>
    </collision>
  </link>
  <joint
    name="J_LFOOT_SENSOR0"
    type="revolute">
    <origin
      xyz="0 0 0"
      rpy="0 0 0" />
    <parent
      link="LFOOT" />
    <child
      link="LFOOT_SENSOR0" />
    <axis
      xyz="0 0 1" />
    <limit upper="0" lower="0" velocity="100" effort="1"/>
  </joint>
  <link
    name="LFOOT_SENSOR1">
    <inertial>
      <origin
        xyz="0 0 0"
        rpy="0 0 0" />
      <mass
        value="0.01" />
      <inertia
        ixx="0.001"
        ixy="0"
        ixz="0"
        iyy="0.001"
        iyz="0"
        izz="0.001" />
    </inertial>
    <visual>
      <origin
        xyz="0.050 0.04 -0.015"
        rpy="0 0 0" />
        <geometry>
          <box size="0.01 0.02 0.01"/>
        </geometry>
      <material
        name="">
        <color
          rgba="0.75294 0.75294 0.75294 1" />
      </material>
    </visual>
    <collision>
      <origin
        xyz="0.050 0.04 -0.015"
        rpy="0 0 0" />
        <geometry>
          <box size="0.01 0.02 0.01"/>
        </geometry>
    </collision>
  </link>
  <joint
    name="J_LFOOT_SENSOR1"
    type="revolute">
    <origin
      xyz="0 0 0"
      rpy="0 0 0" />
    <parent
      link="LFOOT" />
    <child
      link="LFOOT_SENSOR1" />
    <axis
      xyz="0 0 1" />
    <limit upper="0" lower="0" velocity="100" effort="1"/>
  </joint>
  <link
    name="LFOOT_SENSOR2">
    <inertial>
      <origin
        xyz="0 0 0"
        rpy="0 0 0" />
      <mass
        value="0.01" />
      <inertia
        ixx="0.001"
        ixy="0"
        ixz="0"
        iyy="0.001"
        iyz="0"
        izz="0.001" />
    </inertial>
    <visual>
      <origin
        xyz="0.050 0.04 0.17"
        rpy="0 0 0" />
        <geometry>
          <box size="0.01 0.02 0.01"/>
        </geometry>
      <material
        name="">
        <color
          rgba="0.75294 0.75294 0.75294 1" />
      </material>
    </visual>
    <collision>
      <origin
        xyz="0.050 0.04 0.17"
        rpy="0 0 0" />
        <geometry>
          <box size="0.01 0.02 0.01"/>
        </geometry>
    </collision>
  </link>
  <joint
    name="J_LFOOT_SENSOR2"
    type="revolute">
    <origin
      xyz="0 0 0"
      rpy="0 0 0" />
    <parent
      link="LFOOT" />
    <child
      link="LFOOT_SENSOR2" />
    <axis
      xyz="0 0 1" />
    <limit upper="0" lower="0" velocity="100" effort="1"/>
  </joint>
  <link
    name="LFOOT_SENSOR3">
    <inertial>
      <origin
        xyz="0 0 0"
        rpy="0 0 0" />
      <mass
        value="0.01" />
      <inertia
        ixx="0.001"
        ixy="0"
        ixz="0"
        iyy="0.001"
        iyz="0"
        izz="0.001" />
    </inertial>
    <visual>
      <origin
        xyz="-0.065 0.04 0.17"
        rpy="0 0 0" />
        <geometry>
          <box size="0.01 0.02 0.01"/>
        </geometry>
      <material
        name="">
        <color
          rgba="0.75294 0.75294 0.75294 1" />
      </material>
    </visual>
    <collision>
      <origin
        xyz="-0.065 0.04 0.17"
        rpy="0 0 0" />
        <geometry>
          <box size="0.01 0.02 0.01"/>
        </geometry>
    </collision>
  </link>
  <joint
    name="J_LFOOT_SENSOR3"
    type="revolute">
    <origin
      xyz="0 0 0"
      rpy="0 0 0" />
    <parent
      link="LFOOT" />
    <child
      link="LFOOT_SENSOR3" />
	<axis>
		<xyz>0 0 1</xyz>
	</axis>
	<limit upper="0" lower="0" velocity="100" effort="1"/>
  </joint>

  <transmission name="T_HEAD0">
	<type>transmission_interface/SimpleTransmission</type>
	<joint name="J_HEAD0">
	  <hardwareInterface>hardware_interface/EffortJointInterface</hardwareInterface>
	</joint>
	<actuator name="M_HEAD0">
	  <hardwareInterface>hardware_interface/EffortJointInterface</hardwareInterface>
	  <mechanicalReduction>1</mechanicalReduction>
	</actuator>
  </transmission>
  
  <transmission name="T_HEAD1">
	<type>transmission_interface/SimpleTransmission</type>
	<joint name="J_HEAD1">
	  <hardwareInterface>hardware_interface/EffortJointInterface</hardwareInterface>
	</joint>
	<actuator name="M_HEAD1">
	  <hardwareInterface>hardware_interface/EffortJointInterface</hardwareInterface>
	  <mechanicalReduction>1</mechanicalReduction>
	</actuator>
  </transmission>
  
  <transmission name="T_RARM0">
	<type>transmission_interface/SimpleTransmission</type>
	<joint name="J_RARM0">
	  <hardwareInterface>hardware_interface/EffortJointInterface</hardwareInterface>
	</joint>
	<actuator name="M_RARM0">
	  <hardwareInterface>hardware_interface/EffortJointInterface</hardwareInterface>
	  <mechanicalReduction>1</mechanicalReduction>
	</actuator>
  </transmission>

  <transmission name="T_RARM1">
	<type>transmission_interface/SimpleTransmission</type>
	<joint name="J_RARM1">
	  <hardwareInterface>hardware_interface/EffortJointInterface</hardwareInterface>
	</joint>
	<actuator name="M_RARM1">
	  <hardwareInterface>hardware_interface/EffortJointInterface</hardwareInterface>
	  <mechanicalReduction>1</mechanicalReduction>
	</actuator>
  </transmission>
  
    <transmission name="T_RARM2">
	<type>transmission_interface/SimpleTransmission</type>
	<joint name="J_RARM2">
	  <hardwareInterface>hardware_interface/EffortJointInterface</hardwareInterface>
	</joint>
	<actuator name="M_RARM2">
	  <hardwareInterface>hardware_interface/EffortJointInterface</hardwareInterface>
	  <mechanicalReduction>1</mechanicalReduction>
	</actuator>
  </transmission>
  
    <transmission name="T_LARM0">
	<type>transmission_interface/SimpleTransmission</type>
	<joint name="J_LARM0">
	  <hardwareInterface>hardware_interface/EffortJointInterface</hardwareInterface>
	</joint>
	<actuator name="M_LARM0">
	  <hardwareInterface>hardware_interface/EffortJointInterface</hardwareInterface>
	  <mechanicalReduction>1</mechanicalReduction>
	</actuator>
  </transmission>

  <transmission name="T_LARM1">
	<type>transmission_interface/SimpleTransmission</type>
	<joint name="J_LARM1">
	  <hardwareInterface>hardware_interface/EffortJointInterface</hardwareInterface>
	</joint>
	<actuator name="M_LARM1">
	  <hardwareInterface>hardware_interface/EffortJointInterface</hardwareInterface>
	  <mechanicalReduction>1</mechanicalReduction>
	</actuator>
  </transmission>
  
    <transmission name="T_LARM2">
	<type>transmission_interface/SimpleTransmission</type>
	<joint name="J_LARM2">
	  <hardwareInterface>hardware_interface/EffortJointInterface</hardwareInterface>
	</joint>
	<actuator name="M_LARM2">
	  <hardwareInterface>hardware_interface/EffortJointInterface</hardwareInterface>
	  <mechanicalReduction>1</mechanicalReduction>
	</actuator>
  </transmission>

  
  
  
    <transmission name="T_RLEG0">
	<type>transmission_interface/SimpleTransmission</type>
	<joint name="J_RLEG0">
	  <hardwareInterface>hardware_interface/EffortJointInterface</hardwareInterface>
	</joint>
	<actuator name="M_RLEG0">
	  <hardwareInterface>hardware_interface/EffortJointInterface</hardwareInterface>
	  <mechanicalReduction>1</mechanicalReduction>
	</actuator>
  </transmission>

  <transmission name="T_RLEG1">
	<type>transmission_interface/SimpleTransmission</type>
	<joint name="J_RLEG1">
	  <hardwareInterface>hardware_interface/EffortJointInterface</hardwareInterface>
	</joint>
	<actuator name="M_RLEG1">
	  <hardwareInterface>hardware_interface/EffortJointInterface</hardwareInterface>
	  <mechanicalReduction>1</mechanicalReduction>
	</actuator>
  </transmission>
  
    <transmission name="T_RLEG2">
	<type>transmission_interface/SimpleTransmission</type>
	<joint name="J_RLEG2">
	  <hardwareInterface>hardware_interface/EffortJointInterface</hardwareInterface>
	</joint>
	<actuator name="M_RLEG2">
	  <hardwareInterface>hardware_interface/EffortJointInterface</hardwareInterface>
	  <mechanicalReduction>1</mechanicalReduction>
	</actuator>
  </transmission>
  
    <transmission name="T_RLEG3">
	<type>transmission_interface/SimpleTransmission</type>
	<joint name="J_RLEG3">
	  <hardwareInterface>hardware_interface/EffortJointInterface</hardwareInterface>
	</joint>
	<actuator name="M_RLEG3">
	  <hardwareInterface>hardware_interface/EffortJointInterface</hardwareInterface>
	  <mechanicalReduction>1</mechanicalReduction>
	</actuator>
  </transmission>
  
   <transmission name="T_RLEG4">
	<type>transmission_interface/SimpleTransmission</type>
	<joint name="J_RLEG4">
	  <hardwareInterface>hardware_interface/EffortJointInterface</hardwareInterface>
	</joint>
	<actuator name="M_RLEG4">
	  <hardwareInterface>hardware_interface/EffortJointInterface</hardwareInterface>
	  <mechanicalReduction>1</mechanicalReduction>
	</actuator>
  </transmission>
  
  <transmission name="T_RFOOT">
	<type>transmission_interface/SimpleTransmission</type>
	<joint name="J_RFOOT">
	  <hardwareInterface>hardware_interface/EffortJointInterface</hardwareInterface>
	</joint>
	<actuator name="M_RFOOT">
	  <hardwareInterface>hardware_interface/EffortJointInterface</hardwareInterface>
	  <mechanicalReduction>1</mechanicalReduction>
	</actuator>
  </transmission>


    <transmission name="T_LLEG0">
	<type>transmission_interface/SimpleTransmission</type>
	<joint name="J_LLEG0">
	  <hardwareInterface>hardware_interface/EffortJointInterface</hardwareInterface>
	</joint>
	<actuator name="M_LLEG0">
	  <hardwareInterface>hardware_interface/EffortJointInterface</hardwareInterface>
	  <mechanicalReduction>1</mechanicalReduction>
	</actuator>
  </transmission>

  <transmission name="T_LLEG1">
	<type>transmission_interface/SimpleTransmission</type>
	<joint name="J_LLEG1">
	  <hardwareInterface>hardware_interface/EffortJointInterface</hardwareInterface>
	</joint>
	<actuator name="M_LLEG1">
	  <hardwareInterface>hardware_interface/EffortJointInterface</hardwareInterface>
	  <mechanicalReduction>1</mechanicalReduction>
	</actuator>
  </transmission>
  
    <transmission name="T_LLEG2">
	<type>transmission_interface/SimpleTransmission</type>
	<joint name="J_LLEG2">
	  <hardwareInterface>hardware_interface/EffortJointInterface</hardwareInterface>
	</joint>
	<actuator name="M_LLEG2">
	  <hardwareInterface>hardware_interface/EffortJointInterface</hardwareInterface>
	  <mechanicalReduction>1</mechanicalReduction>
	</actuator>
  </transmission>
  
    <transmission name="T_LLEG3">
	<type>transmission_interface/SimpleTransmission</type>
	<joint name="J_LLEG3">
	  <hardwareInterface>hardware_interface/EffortJointInterface</hardwareInterface>
	</joint>
	<actuator name="M_LLEG3">
	  <hardwareInterface>hardware_interface/EffortJointInterface</hardwareInterface>
	  <mechanicalReduction>1</mechanicalReduction>
	</actuator>
  </transmission>
  
   <transmission name="T_LLEG4">
	<type>transmission_interface/SimpleTransmission</type>
	<joint name="J_LLEG4">
	  <hardwareInterface>hardware_interface/EffortJointInterface</hardwareInterface>
	</joint>
	<actuator name="M_LLEG4">
	  <hardwareInterface>hardware_interface/EffortJointInterface</hardwareInterface>
	  <mechanicalReduction>1</mechanicalReduction>
	</actuator>
  </transmission>
  
  <transmission name="T_LFOOT">
	<type>transmission_interface/SimpleTransmission</type>
	<joint name="J_LFOOT">
	  <hardwareInterface>hardware_interface/EffortJointInterface</hardwareInterface>
	</joint>
	<actuator name="M_LFOOT">
	  <hardwareInterface>hardware_interface/EffortJointInterface</hardwareInterface>
	  <mechanicalReduction>1</mechanicalReduction>
	</actuator>
  </transmission>



  
</robot>
