<?xml version="1.0"?>
<robot
  name="SAKURA">	
  <gazebo reference="imu_link">
    <gravity>true</gravity>
    <sensor name="imu_sensor" type="imu">
      <always_on>true</always_on>
      <update_rate>125</update_rate>
      <visualize>true</visualize>
      <topic>__default_topic__</topic>
      <plugin filename="libgazebo_ros_imu_sensor.so" name="imu_plugin">
        <topicName>imu/data_raw</topicName>
        <bodyName>imu_link</bodyName>
        <updateRateHZ>125.0</updateRateHZ>
        <gaussianNoise>0.0</gaussianNoise>
        <xyzOffset>0 0 0</xyzOffset>
        <rpyOffset>0 0 0</rpyOffset>
        <frameName>imu_link</frameName>
      </plugin>
      <pose>0 0 0 0 0 0</pose>
    </sensor>
  </gazebo>
  <gazebo>
    <plugin filename="libgazebo_ros_control.so" name="gazebo_ros_control">
      <robotNamespace>/SAKURA</robotNamespace>
      <robotSimType>gazebo_ros_control/DefaultRobotHWSim</robotSimType>
    </plugin>
  </gazebo>
  <gazebo reference="J_HEAD">
	<stopErp>0.2</stopErp>
	<provideFeedback>true</provideFeedback>
  </gazebo>  
  <gazebo reference="J_LARM0">
	<stopErp>0.2</stopErp>
	<provideFeedback>true</provideFeedback>
  </gazebo>  
  <gazebo reference="J_LARM1">
	<stopErp>0.2</stopErp>
	<provideFeedback>true</provideFeedback>
  </gazebo>  
  <gazebo reference="J_LARM2">
	<stopErp>0.2</stopErp>
	<provideFeedback>true</provideFeedback>
  </gazebo>  
  <gazebo reference="J_RARM0">
	<stopErp>0.2</stopErp>
	<provideFeedback>true</provideFeedback>
  </gazebo>  
  <gazebo reference="J_RARM1">
	<stopErp>0.2</stopErp>
	<provideFeedback>true</provideFeedback>
  </gazebo>  
  <gazebo reference="J_LLEG0">
	<stopErp>0.2</stopErp>
	<provideFeedback>true</provideFeedback>
  </gazebo>  
  <gazebo reference="J_LLEG1">
	<stopErp>0.2</stopErp>
	<provideFeedback>true</provideFeedback>
  </gazebo>  
  <gazebo reference="J_LLEG2">
	<stopErp>0.2</stopErp>
	<provideFeedback>true</provideFeedback>
  </gazebo>  
  <gazebo reference="J_LLEG3">
	<stopErp>0.2</stopErp>
	<provideFeedback>true</provideFeedback>
  </gazebo>  
  <gazebo reference="J_LLEG4">
	<stopErp>0.2</stopErp>
	<provideFeedback>true</provideFeedback>
  </gazebo>  
  <gazebo reference="J_RLEG0">
	<stopErp>0.2</stopErp>
	<provideFeedback>true</provideFeedback>
  </gazebo>  
  <gazebo reference="J_RLEG1">
	<stopErp>0.2</stopErp>
	<provideFeedback>true</provideFeedback>
  </gazebo>  
  <gazebo reference="J_RLEG2">
	<stopErp>0.2</stopErp>
	<provideFeedback>true</provideFeedback>
  </gazebo>  
  <gazebo reference="J_RLEG3">
	<stopErp>0.2</stopErp>
	<provideFeedback>true</provideFeedback>
  </gazebo>  
  <gazebo reference="J_RLEG4">
	<stopErp>0.2</stopErp>
	<provideFeedback>true</provideFeedback>
  </gazebo> 
  <gazebo reference="J_RARM2">
	<stopErp>0.2</stopErp>
	<provideFeedback>true</provideFeedback>
  </gazebo> 
  <gazebo reference="J_LFOOT">
	<stopErp>0.2</stopErp>
	<provideFeedback>true</provideFeedback>
  </gazebo>  
  <gazebo reference="J_RFOOT">
	<stopErp>0.2</stopErp>
	<provideFeedback>true</provideFeedback>
  </gazebo>  
  <gazebo reference="RFOOT">
    <mu1>1.0</mu1>
    <mu2>1.0</mu2>
    <kp>1220000.0</kp>
    <kd>1.0</kd> <!---->
  </gazebo>
  <gazebo reference="LFOOT">
    <mu1>1.0</mu1>
    <mu2>1.0</mu2>
    <kp>1220000.0</kp>
    <kd>1.0</kd> <!---->
  </gazebo>
  
<!-- FT SENSORS -->
  <gazebo>
	<plugin name="ft_sensor" filename="libgazebo_ros_ft_sensor.so">
	  <updateRate>100.0</updateRate>
	  <topicName>ft_sensor_larm0</topicName>
	  <jointName>J_LARM0</jointName>
	</plugin>
  </gazebo>
  <gazebo>
	<plugin name="ft_sensor" filename="libgazebo_ros_ft_sensor.so">
	  <updateRate>100.0</updateRate>
	  <topicName>ft_sensor_larm1</topicName>
	  <jointName>J_LARM1</jointName>
	</plugin>
  </gazebo>
  <gazebo>
	<plugin name="ft_sensor" filename="libgazebo_ros_ft_sensor.so">
	  <updateRate>100.0</updateRate>
	  <topicName>ft_sensor_larm2</topicName>
	  <jointName>J_LARM2</jointName>
	</plugin>
  </gazebo>
  
  
    <gazebo>
	<plugin name="ft_sensor" filename="libgazebo_ros_ft_sensor.so">
	  <updateRate>100.0</updateRate>
	  <topicName>ft_sensor_rarm0</topicName>
	  <jointName>J_RARM0</jointName>
	</plugin>
  </gazebo>
  <gazebo>
	<plugin name="ft_sensor" filename="libgazebo_ros_ft_sensor.so">
	  <updateRate>100.0</updateRate>
	  <topicName>ft_sensor_rarm1</topicName>
	  <jointName>J_RARM1</jointName>
	</plugin>
  </gazebo>
  <gazebo>
	<plugin name="ft_sensor" filename="libgazebo_ros_ft_sensor.so">
	  <updateRate>100.0</updateRate>
	  <topicName>ft_sensor_rarm2</topicName>
	  <jointName>J_RARM2</jointName>
	</plugin>
  </gazebo>
  
  
  
  <gazebo>
	<plugin name="ft_sensor" filename="libgazebo_ros_ft_sensor.so">
	  <updateRate>100.0</updateRate>
	  <topicName>ft_sensor_lleg0</topicName>
	  <jointName>J_LLEG0</jointName>
	</plugin>
  </gazebo>
    <gazebo>
	<plugin name="ft_sensor" filename="libgazebo_ros_ft_sensor.so">
	  <updateRate>100.0</updateRate>
	  <topicName>ft_sensor_lleg1</topicName>
	  <jointName>J_LLEG1</jointName>
	</plugin>
  </gazebo>
    <gazebo>
	<plugin name="ft_sensor" filename="libgazebo_ros_ft_sensor.so">
	  <updateRate>100.0</updateRate>
	  <topicName>ft_sensor_lleg2</topicName>
	  <jointName>J_LLEG2</jointName>
	</plugin>
  </gazebo>
    <gazebo>
	<plugin name="ft_sensor" filename="libgazebo_ros_ft_sensor.so">
	  <updateRate>100.0</updateRate>
	  <topicName>ft_sensor_lleg3</topicName>
	  <jointName>J_LLEG3</jointName>
	</plugin>
  </gazebo>
    <gazebo>
	<plugin name="ft_sensor" filename="libgazebo_ros_ft_sensor.so">
	  <updateRate>100.0</updateRate>
	  <topicName>ft_sensor_lleg4</topicName>
	  <jointName>J_LLEG4</jointName>
	</plugin>
  </gazebo>
    <gazebo>
	<plugin name="ft_sensor" filename="libgazebo_ros_ft_sensor.so">
	  <updateRate>100.0</updateRate>
	  <topicName>ft_sensor_lfoot</topicName>
	  <jointName>J_LFOOT</jointName>
	</plugin>
  </gazebo>
  
    <gazebo>
	<plugin name="ft_sensor" filename="libgazebo_ros_ft_sensor.so">
	  <updateRate>100.0</updateRate>
	  <topicName>ft_sensor_rleg0</topicName>
	  <jointName>J_RLEG0</jointName>
	</plugin>
  </gazebo>
    <gazebo>
	<plugin name="ft_sensor" filename="libgazebo_ros_ft_sensor.so">
	  <updateRate>100.0</updateRate>
	  <topicName>ft_sensor_rleg1</topicName>
	  <jointName>J_RLEG1</jointName>
	</plugin>
  </gazebo>
    <gazebo>
	<plugin name="ft_sensor" filename="libgazebo_ros_ft_sensor.so">
	  <updateRate>100.0</updateRate>
	  <topicName>ft_sensor_rleg2</topicName>
	  <jointName>J_RLEG2</jointName>
	</plugin>
  </gazebo>
    <gazebo>
	<plugin name="ft_sensor" filename="libgazebo_ros_ft_sensor.so">
	  <updateRate>100.0</updateRate>
	  <topicName>ft_sensor_rleg3</topicName>
	  <jointName>J_RLEG3</jointName>
	</plugin>
  </gazebo>
    <gazebo>
	<plugin name="ft_sensor" filename="libgazebo_ros_ft_sensor.so">
	  <updateRate>100.0</updateRate>
	  <topicName>ft_sensor_rleg4</topicName>
	  <jointName>J_RLEG4</jointName>
	</plugin>
  </gazebo>
    <gazebo>
	<plugin name="ft_sensor" filename="libgazebo_ros_ft_sensor.so">
	  <updateRate>100.0</updateRate>
	  <topicName>ft_sensor_rfoot</topicName>
	  <jointName>J_RFOOT</jointName>
	</plugin>
  </gazebo>
  
  
  

  <link name="world">  </link>
  
  <link name="imu_link">
    <collision>
      <origin xyz="0 0 0" rpy="0 0 0"/>
      <geometry>
    <box size="0.01 0.01 0.01"/>
      </geometry>
    </collision>

    <visual>
      <origin xyz="0 0 0" rpy="0 0 0"/>
      <geometry>
    <box size="0.01 0.01 0.01"/>
      </geometry>
      <material name="red"/>
    </visual>

    <inertial>
      <mass value="1e-5" />
      <origin xyz="0 0 0" rpy="0 0 0"/>
      <inertia ixx="1e-6" ixy="0" ixz="0" iyy="1e-6" iyz="0" izz="1e-6" />
    </inertial>
  </link>
  <joint name="imu_joint" type="fixed">
    <axis xyz="-1 0 0" />
    <origin xyz="0 0 0" rpy="0 0 0"/>
    <parent link="TRUNK"/>
    <child link="imu_link"/>
  </joint>
  
  
  
  
  <link
    name="TRUNK">
    <inertial>
      <origin
        xyz="-0.000142944293532541 -0.0159940135836359 0.119253638413231"
        rpy="0 0 0" />
      <mass
        value="1.4778155091901" />
      <inertia
        ixx="0.0125398154437975"
        ixy="-2.68478156217668E-06"
        ixz="-7.17353402812125E-06"
        iyy="0.016695640033345"
        iyz="0.000776177026664091"
        izz="0.01567882258573842" />
    </inertial>
    <visual>
      <origin
        xyz="0 0 0"
        rpy="0 0 0" />
      <geometry>
        <mesh
          filename="package://sakura_description/meshes/TRUNK.STL" />
      </geometry>
      <material
        name="">
        <color
          rgba="0.752941176470588 0.752941176470588 0.752941176470588 1" />
      </material>
    </visual>
  </link>
  <joint name="fixed" type="floating">
    <parent link="world"/>
    <child link="TRUNK"/>
    <origin xyz="0 0 0.50" rpy="0 0 0"/>
  </joint>
  <link
    name="HEAD">
    <inertial>
      <origin
        xyz="-0.0038811 0.012249 0.048965"
        rpy="0 0 0" />
      <mass
        value="0.21462" />
      <inertia
        ixx="0.00110122"
        ixy="8.917E-07"
        ixz="4.6738E-06"
        iyy="0.001"
        iyz="-1.8633E-05"
        izz="0.001" />
    </inertial>
    <visual>
      <origin
        xyz="0 0 0"
        rpy="0 0 0" />
      <geometry>
        <mesh
          filename="package://sakura_description/meshes/HEAD.STL" />
      </geometry>
      <material
        name="">
        <color
          rgba="0.75294 0.75294 0.75294 1" />
      </material>
    </visual>
  </link>
  <joint
    name="J_HEAD"
    type="continuous">
    <origin
      xyz="0.0016 0.01125 0.2484"
      rpy="-1.2005E-15 -9.4278E-17 -2.3904E-16" />
    <parent
      link="TRUNK" />
    <child
      link="HEAD" />
    <axis
      xyz="0 0 1" />
    <limit
      effort="10"
      velocity="8.58" />
    <dynamics 
	  damping="0.7"
	  friction="0.5"/>
  </joint>
  <link
    name="LARM0">
    <inertial>
      <origin
        xyz="4.16333634234434E-17 2.77555756156289E-17 0.0103025666414173"
        rpy="0 0 0" />
      <mass
        value="0.0066175226097181" />
      <inertia
        ixx="1.E-03"
        ixy="0"
        ixz="0"
        iyy="1.E-03"
        iyz="0"
        izz="1.E-03" />
    </inertial>
    <visual>
      <origin
        xyz="0 0 0"
        rpy="0 0 0" />
      <geometry>
        <mesh
          filename="package://sakura_description/meshes/LARM0.STL" />
      </geometry>
      <material
        name="">
        <color
          rgba="0.792156862745098 0.819607843137255 0.933333333333333 1" />
      </material>
    </visual>
  </link>
  <joint
    name="J_LARM0"
    type="continuous">
    <origin
      xyz="-0.0935 -0.038 0.209"
      rpy="1.5708 3.14159 -1.5708" />
    <parent
      link="TRUNK" />
    <child
      link="LARM0" />
    <axis
      xyz="0 0 1" />
    <limit
      effort="10"
      velocity="8.58" />
    <dynamics 
     damping="0.7"
     friction="0.5"/>
  </joint>
  <link
    name="LARM1">
    <inertial>
      <origin
        xyz="-0.000203905909046856 -0.0358166170046635 -0.030724518771744"
        rpy="0 0 0" />
      <mass
        value="0.386889741732442" />
      <inertia
        ixx="0.001319462933467775"
        ixy="-7.00859671208955E-06"
        ixz="-6.33921748509821E-09"
        iyy="0.001"
        iyz="6.46973244600118E-07"
        izz="0.001386423060557297" />
    </inertial>
    <visual>
      <origin
        xyz="0 0 0"
        rpy="0 0 0" />
      <geometry>
        <mesh
          filename="package://sakura_description/meshes/LARM1.STL" />
      </geometry>
      <material
        name="">
        <color
          rgba="0.898039215686275 0.92156862745098 0.929411764705882 1" />
      </material>
    </visual>
  </link>
  <joint
    name="J_LARM1"
    type="continuous">
    <origin
      xyz="-0.0308 0 0.036"
      rpy="3.1416 1.5708 0" />
    <parent
      link="LARM0" />
    <child
      link="LARM1" />
    <axis
      xyz="0 0 -1" />
    <limit
      effort="10"
      velocity="8.58" />
        <dynamics 
     damping="0.7"
     friction="0.5"/>
  </joint>
  <link
    name="LARM2">
    <inertial>
      <origin
        xyz="-0.000946892853796732 -0.0604743903550126 -0.030549305382329"
        rpy="0 0 0" />
      <mass
        value="0.417770884687889" />
      <inertia
        ixx="0.00130365609096481"
        ixy="-2.20058971275383E-05"
        ixz="-1.13235654810576E-07"
        iyy="0.001"
        iyz="-4.76741794550902E-06"
        izz="0.00130522583526536" />
    </inertial>
    <visual>
      <origin
        xyz="0 0 0"
        rpy="0 0 0" />
      <geometry>
        <mesh
          filename="package://sakura_description/meshes/LARM2.STL" />
      </geometry>
      <material
        name="">
        <color
          rgba="0.898039215686275 0.92156862745098 0.929411764705882 1" />
      </material>
    </visual>
  </link>
  <joint
    name="J_LARM2"
    type="continuous">
    <origin
      xyz="0.0307 -0.1235 -0.0308"
      rpy="0 1.5708 0" />
    <parent
      link="LARM1" />
    <child
      link="LARM2" />
    <axis
      xyz="0 0 -1" />
    <limit
      effort="10"
      velocity="8.58" />
        <dynamics 
     damping="0.7"
     friction="0.5"/>
  </joint>
  <link
    name="RARM0">
    <inertial>
      <origin
        xyz="-4.16333634234434E-17 0 0.0103025666414173"
        rpy="0 0 0" />
      <mass
        value="0.00661752260971814" />
      <inertia
        ixx="1.E-03"
        ixy="0"
        ixz="0"
        iyy="1.E-03"
        iyz="0"
        izz="1.E-03" />
    </inertial>
    <visual>
      <origin
        xyz="0 0 0"
        rpy="0 0 0" />
      <geometry>
        <mesh
          filename="package://sakura_description/meshes/RARM0.STL" />
      </geometry>
      <material
        name="">
        <color
          rgba="0.792156862745098 0.819607843137255 0.933333333333333 1" />
      </material>
    </visual>
  </link>
  <joint
    name="J_RARM0"
    type="continuous">
    <origin
      xyz="0.0935 -0.038 0.209"
      rpy="-1.5708 -6.1121E-16 -1.5708" />
    <parent
      link="TRUNK" />
    <child
      link="RARM0" />
    <axis
      xyz="0 0 1" />
    <limit
      effort="10"
      velocity="8.58" />
        <dynamics 
     damping="0.7"
     friction="0.5"/>
  </joint>
  <link
    name="RARM1">
    <inertial>
      <origin
        xyz="-0.00020391 -0.035817 -0.030725"
        rpy="0 0 0" />
      <mass
        value="0.38689" />
      <inertia
        ixx="0.00131946"
        ixy="-7.0086E-06"
        ixz="-6.3392E-09"
        iyy="0.001"
        iyz="6.4697E-07"
        izz="0.00138642" />
    </inertial>
    <visual>
      <origin
        xyz="0 0 0"
        rpy="0 0 0" />
      <geometry>
        <mesh
          filename="package://sakura_description/meshes/RARM1.STL" />
      </geometry>
      <material
        name="">
        <color
          rgba="0.89804 0.92157 0.92941 1" />
      </material>
    </visual>
  </link>
  <joint
    name="J_RARM1"
    type="continuous">
    <origin
      xyz="-0.0308 0 0.036"
      rpy="3.1416 1.5708 0" />
    <parent
      link="RARM0" />
    <child
      link="RARM1" />
    <axis
      xyz="0 0 1" />
    <limit
      effort="10"
      velocity="8.58" />
        <dynamics 
     damping="0.7"
     friction="0.5"/>
  </joint>
  <link
    name="RARM2">
    <inertial>
      <origin
        xyz="-0.000946892853796774 -0.0604743903550127 -0.0305493053823289"
        rpy="0 0 0" />
      <mass
        value="0.417770884687889" />
      <inertia
        ixx="0.00130365609096481"
        ixy="-2.20058971275389E-05"
        ixz="-1.13235654810633E-07"
        iyy="0.001"
        iyz="-4.76741794550966E-06"
        izz="0.00130522583526536" />
    </inertial>
    <visual>
      <origin
        xyz="0 0 0"
        rpy="0 0 0" />
      <geometry>
        <mesh
          filename="package://sakura_description/meshes/RARM2.STL" />
      </geometry>
      <material
        name="">
        <color
          rgba="0.898039215686275 0.92156862745098 0.929411764705882 1" />
      </material>
    </visual>
  </link>
  <joint
    name="J_RARM2"
    type="continuous">
    <origin
      xyz="0.0307 -0.1235 -0.0308"
      rpy="0 1.5708 0" />
    <parent
      link="RARM1" />
    <child
      link="RARM2" />
    <axis
      xyz="0 0 -1" />
    <limit
      effort="10"
      velocity="8.58" />
        <dynamics 
     damping="0.7"
     friction="0.5"/>
  </joint>
  <link
    name="LLEG0">
    <inertial>
      <origin
        xyz="1.38777878078145E-17 1.38777878078145E-17 0.012339611662812"
        rpy="0 0 0" />
      <mass
        value="0.137487098095279" />
      <inertia
        ixx="0.001"
        ixy="0"
        ixz="0"
        iyy="0.001"
        iyz="0"
        izz="0.001" />
    </inertial>
    <visual>
      <origin
        xyz="0 0 0"
        rpy="0 0 0" />
      <geometry>
        <mesh
          filename="package://sakura_description/meshes/LLEG0.STL" />
      </geometry>
      <material
        name="">
        <color
          rgba="0.650980392156863 0.619607843137255 0.588235294117647 1" />
      </material>
    </visual>
  </link>
  <joint
    name="J_LLEG0"
    type="continuous">
    <origin
      xyz="-0.055 -0.018 -0.005"
      rpy="-3.14159265358979 1.21430643318376E-16 -1.5707963267949" />
    <parent
      link="TRUNK" />
    <child
      link="LLEG0" />
    <axis
      xyz="0 0 1" />
    <limit
      effort="10"
      velocity="8.58" />
        <dynamics 
     damping="0.7"
     friction="0.5"/>
  </joint>
  <link
    name="LLEG1">
    <inertial>
      <origin
        xyz="-4.90216563097182E-05 -0.014933566350856 -0.0542307430726147"
        rpy="0 0 0" />
      <mass
        value="0.484317524341268" />
      <inertia
        ixx="0.001258532465487086"
        ixy="-1.08430216395215E-08"
        ixz="-4.93107012410751E-07"
        iyy="0.001256538006237082"
        iyz="8.86337248194806E-06"
        izz="0.001" />
    </inertial>
    <visual>
      <origin
        xyz="0 0 0"
        rpy="0 0 0" />
      <geometry>
        <mesh
          filename="package://sakura_description/meshes/LLEG1.STL" />
      </geometry>
      <material
        name="">
        <color
          rgba="0.752941176470588 0.752941176470588 0.752941176470588 1" />
      </material>
    </visual>
  </link>
  <joint
    name="J_LLEG1"
    type="continuous">
    <origin
      xyz="0.056 0 0.036"
      rpy="-1.5707963267949 -1.22338662637834E-16 -1.5707963267949" />
    <parent
      link="LLEG0" />
    <child
      link="LLEG1" />
    <axis
      xyz="0 0 -1" />
    <limit
      effort="10"
      velocity="8.58" />
        <dynamics 
     damping="0.7"
     friction="0.5"/>
  </joint>
  
  <link
    name="LLEG1_BACK">
    <inertial>
      <origin
        xyz="0 0 0"
        rpy="0 0 0" />
      <mass
        value="0.001" />
      <inertia
        ixx="0.00001"
        ixy="-8.9555E-06"
        ixz="-2.1884E-05"
        iyy="0.00001"
        iyz="-1.9325E-05"
        izz="0.00001" />
    </inertial>
  </link>
  <joint
    name="J_LLEG1_BACK"
    type="revolute">
    <origin
      xyz="0 0 0"
      rpy="0 0 0" />
    <parent
      link="LLEG1" />
    <child
      link="LLEG1_BACK" />
    <axis
      xyz="0 0 1" />
    <limit
      upper="0.01"
      lower="0.01"
      effort="10"
      velocity="8.58" />
        <dynamics 
     damping="0.7"
     friction="0.5"/>
  </joint>
  
  
  <link
    name="LLEG2">
    <inertial>
      <origin
        xyz="0.0896135033902749 -0.121669815792639 -0.0285739776731877"
        rpy="0 0 0" />
      <mass
        value="0.429581814867276" />
      <inertia
        ixx="0.001739443276879588"
        ixy="0.000469298592224479"
        ixz="-4.17657698668898E-06"
        iyy="0.00145781924000273"
        iyz="4.49877955818474E-06"
        izz="0.00100793675092908" />
    </inertial>
    <visual>
      <origin
        xyz="0 0 0"
        rpy="0 0 0" />
      <geometry>
        <mesh
          filename="package://sakura_description/meshes/LLEG2.STL" />
      </geometry>
      <material
        name="">
        <color
          rgba="0.752941176470588 0.752941176470588 0.752941176470588 1" />
      </material>
    </visual>
  </link>
  <joint
    name="J_LLEG2"
    type="continuous">
    <origin
      xyz="0.0289999999999999 0 -0.0750000000000234"
      rpy="-1.5707963267949 0.78539816339745 -1.5707963267949" />
    <parent
      link="LLEG1_BACK" />
    <child
      link="LLEG2" />
    <axis
      xyz="0 0 1" />
    <limit
      effort="10"
      velocity="8.58" />
        <dynamics 
     damping="0.7"
     friction="0.5"/>
  </joint>
  
  <link
    name="LLEG2_BACK">
    <inertial>
      <origin
        xyz="0 0 0"
        rpy="0 0 0" />
      <mass
        value="0.001" />
      <inertia
        ixx="0.00001"
        ixy="-8.9555E-06"
        ixz="-2.1884E-05"
        iyy="0.00001"
        iyz="-1.9325E-05"
        izz="0.00001" />
    </inertial>
  </link>
  <joint
    name="J_LLEG2_BACK"
    type="revolute">
    <origin
      xyz="0 0 0"
      rpy="0 0 0" />
    <parent
      link="LLEG2" />
    <child
      link="LLEG2_BACK" />
    <axis
      xyz="0 0 1" />
    <limit
      upper="0.01"
      lower="0.01"
      effort="10"
      velocity="8.58" />
        <dynamics 
     damping="0.7"
     friction="0.5"/>
  </joint>
  
  
  <link
    name="LLEG3">
    <inertial>
      <origin
        xyz="0.0938607247050214 0.021121469241447 -0.0266864244548486"
        rpy="0 0 0" />
      <mass
        value="0.253457988874213" />
      <inertia
        ixx="0.001157893827081503"
        ixy="4.33507693026071E-06"
        ixz="2.38137513758817E-06"
        iyy="0.001215254509125973"
        iyz="4.49605098935315E-06"
        izz="0.001" />
    </inertial>
    <visual>
      <origin
        xyz="0 0 0"
        rpy="0 0 0" />
      <geometry>
        <mesh
          filename="package://sakura_description/meshes/LLEG3.STL" />
      </geometry>
      <material
        name="">
        <color
          rgba="0.752941176470588 0.752941176470588 0.752941176470588 1" />
      </material>
    </visual>
  </link>
  <joint
    name="J_LLEG3"
    type="continuous">
    <origin
      xyz="0.112429978208667 -0.169643181644254 0.00160000000000024"
      rpy="-0.0320557226319531 0.0283578707512148 -1.01721646459287" />
    <parent
      link="LLEG2_BACK" />
    <child
      link="LLEG3" />
    <axis
      xyz="-0.0283540701513945 -0.0320373469653184 0.999084408398647" />
    <limit
      effort="10"
      velocity="8.58" />
        <dynamics 
     damping="0.7"
     friction="0.5"/>  
  </joint>
  
    <link
    name="LLEG3_BACK">
    <inertial>
      <origin
        xyz="0 0 0"
        rpy="0 0 0" />
      <mass
        value="0.001" />
      <inertia
        ixx="0.00001"
        ixy="-8.9555E-06"
        ixz="-2.1884E-05"
        iyy="0.00001"
        iyz="-1.9325E-05"
        izz="0.00001" />
    </inertial>
  </link>
  <joint
    name="J_LLEG3_BACK"
    type="revolute">
    <origin
      xyz="0 0 0"
      rpy="0 0 0" />
    <parent
      link="LLEG3" />
    <child
      link="LLEG3_BACK" />
    <axis
      xyz="0 0 1" />
    <limit
      upper="0.01"
      lower="0.01"
      effort="10"
      velocity="8.58" />
        <dynamics 
     damping="0.7"
     friction="0.5"/>
  </joint>

  
  
  <link
    name="LLEG4">
    <inertial>
      <origin
        xyz="0.0207692569273853 -0.0149335663508559 -0.0309509783436903"
        rpy="0 0 0" />
      <mass
        value="0.484317524341267" />
      <inertia
        ixx="0.001"
        ixy="8.86337248194725E-06"
        ixz="4.93107012410836E-07"
        iyy="0.001256538006237082"
        iyz="1.08430216395228E-08"
        izz="0.001258532465487085" />
    </inertial>
    <visual>
      <origin
        xyz="0 0 0"
        rpy="0 0 0" />
      <geometry>
        <mesh
          filename="package://sakura_description/meshes/LLEG4.STL" />
      </geometry>
      <material
        name="">
        <color
          rgba="0.752941176470588 0.752941176470588 0.752941176470588 1" />
      </material>
    </visual>
  </link>
  <joint
    name="J_LLEG4"
    type="continuous">
    <origin
      xyz="0.19759 0.040682 0.007913"
      rpy="0.034963 0.024684 -1.339" />
    <parent
      link="LLEG3_BACK" />
    <child
      link="LLEG4" />
    <axis
      xyz="0 0 -1" />
    <limit
      effort="10"
      velocity="8.58" />
        <dynamics 
     damping="0.7"
     friction="0.5"/>
  </joint>
  
  <link
    name="LLEG4_BACK">
    <inertial>
      <origin
        xyz="0 0 0"
        rpy="0 0 0" />
      <mass
        value="0.001" />
      <inertia
        ixx="0.00001"
        ixy="-8.9555E-06"
        ixz="-2.1884E-05"
        iyy="0.00001"
        iyz="-1.9325E-05"
        izz="0.00001" />
    </inertial>
  </link>
  <joint
    name="J_LLEG4_BACK"
    type="revolute">
    <origin
      xyz="0 0 0"
      rpy="0 0 0" />
    <parent
      link="LLEG4" />
    <child
      link="LLEG4_BACK" />
    <axis
      xyz="0 0 1" />
    <limit
      upper="0.01"
      lower="0.01"
      effort="10"
      velocity="8.58" />
        <dynamics 
     damping="0.1"
     friction="0.1"/>
  </joint>
  
  <link
    name="LFOOT">
    <inertial>
      <origin
        xyz="-0.00984398078216434 0.033081446163245 0.0742424926896279"
        rpy="0 0 0" />
      <mass
        value="0.474832547151362" />
      <inertia
        ixx="0.001"
        ixy="8.95545085142721E-06"
        ixz="2.1883900378474E-05"
        iyy="0.001"
        iyz="-1.93251189181957E-05"
        izz="0.001" />
    </inertial>
    <visual>
      <origin
        xyz="0 0 0"
        rpy="0 0 0" />
      <geometry>
        <mesh
          filename="package://sakura_description/meshes/LFOOT.STL" />
      </geometry>
      <material
        name="">
        <color
          rgba="0.752941176470588 0.752941176470588 0.752941176470588 1" />
      </material>
    </visual>
    <collision>
      <origin
        xyz="0 0 0"
        rpy="0 0 0" />
      <geometry>
        <mesh
          filename="package://sakura_description/meshes/LFOOT.STL" />
      </geometry>
    </collision>
  </link>
  <joint
    name="J_LFOOT"
    type="continuous">
    <origin
      xyz="0.072 0 -0.031"
      rpy="0 -1.5708 0" />
    <parent
      link="LLEG4_BACK" />
    <child
      link="LFOOT" />
    <axis
      xyz="0 0 -1" />
    <limit
      effort="10"
      velocity="8.58" />
        <dynamics 
     damping="0.7"
     friction="0.5"/>
  </joint>
  <link
    name="RLEG0">
    <inertial>
      <origin
        xyz="0 1.38777878078145E-17 0.012339611662812"
        rpy="0 0 0" />
      <mass
        value="0.137487098095279" />
      <inertia
        ixx="0.001"
        ixy="0"
        ixz="0"
        iyy="0.001"
        iyz="0"
        izz="0.001" />
    </inertial>
    <visual>
      <origin
        xyz="0 0 0"
        rpy="0 0 0" />
      <geometry>
        <mesh
          filename="package://sakura_description/meshes/RLEG0.STL" />
      </geometry>
      <material
        name="">
        <color
          rgba="0.650980392156863 0.619607843137255 0.588235294117647 1" />
      </material>
    </visual>
  </link>
  <joint
    name="J_RLEG0"
    type="continuous">
    <origin
      xyz="0.055 -0.018 -0.005"
      rpy="-3.14159265358979 1.21430643318376E-16 -1.5707963267949" />
    <parent
      link="TRUNK" />
    <child
      link="RLEG0" />
    <axis
      xyz="0 0 1" />
    <limit
      effort="10"
      velocity="8.58" />
        <dynamics 
     damping="0.7"
     friction="0.5"/>
  </joint>
  <link
    name="RLEG1">
    <inertial>
      <origin
        xyz="-4.9022E-05 -0.014934 -0.054231"
        rpy="0 0 0" />
      <mass
        value="0.48432" />
      <inertia
        ixx="0.00125853"
        ixy="-1.0843E-08"
        ixz="-4.9311E-07"
        iyy="0.00125654"
        iyz="8.8634E-06"
        izz="0.001" />
    </inertial>
    <visual>
      <origin
        xyz="0 0 0"
        rpy="0 0 0" />
      <geometry>
        <mesh
          filename="package://sakura_description/meshes/RLEG1.STL" />
      </geometry>
      <material
        name="">
        <color
          rgba="0.75294 0.75294 0.75294 1" />
      </material>
    </visual>
  </link>
  <joint
    name="J_RLEG1"
    type="continuous">
    <origin
      xyz="0.056 0 0.036"
      rpy="-1.5707963267949 2.66239395980971E-16 -1.5707963267949" />
    <parent
      link="RLEG0" />
    <child
      link="RLEG1" />
    <axis
      xyz="0 0 -1" />
    <limit
      effort="10"
      velocity="8.58" />
        <dynamics 
     damping="0.7"
     friction="0.5"/>
  </joint>
  
    <link
    name="RLEG1_BACK">
    <inertial>
      <origin
        xyz="0 0 0"
        rpy="0 0 0" />
      <mass
        value="0.001" />
      <inertia
        ixx="0.00001"
        ixy="-8.9555E-06"
        ixz="-2.1884E-05"
        iyy="0.00001"
        iyz="-1.9325E-05"
        izz="0.00001" />
    </inertial>
  </link>
  <joint
    name="J_RLEG1_BACK"
    type="revolute">
    <origin
      xyz="0 0 0"
      rpy="0 0 0" />
    <parent
      link="RLEG1" />
    <child
      link="RLEG1_BACK" />
    <axis
      xyz="0 0 1" />
    <limit
      upper="0.01"
      lower="0.01"
      effort="10"
      velocity="8.58" />
        <dynamics 
     damping="0.7"
     friction="0.5"/>
  </joint>

  
  <link
    name="RLEG2">
    <inertial>
      <origin
        xyz="0.089613503390275 -0.121669815792639 -0.0285739776731877"
        rpy="0 0 0" />
      <mass
        value="0.429581814867276" />
      <inertia
        ixx="0.001739443276879589"
        ixy="0.00046929859222448"
        ixz="-4.17657698668821E-06"
        iyy="0.001457819240002731"
        iyz="4.49877955818371E-06"
        izz="0.00100793675092908" />
    </inertial>
    <visual>
      <origin
        xyz="0 0 0"
        rpy="0 0 0" />
      <geometry>
        <mesh
          filename="package://sakura_description/meshes/RLEG2.STL" />
      </geometry>
      <material
        name="">
        <color
          rgba="0.752941176470588 0.752941176470588 0.752941176470588 1" />
      </material>
    </visual>
  </link>
  <joint
    name="J_RLEG2"
    type="continuous">
    <origin
      xyz="0.0290000000000001 0 -0.075"
      rpy="-1.5707963267949 0.78539816339745 -1.5707963267949" />
    <parent
      link="RLEG1_BACK" />
    <child
      link="RLEG2" />
    <axis
      xyz="0 0 -1" />
    <limit
      effort="10"
      velocity="8.58" />
        <dynamics 
     damping="0.7"
     friction="0.5"/>
  </joint>
  
    <link
    name="RLEG2_BACK">
    <inertial>
      <origin
        xyz="0 0 0"
        rpy="0 0 0" />
      <mass
        value="0.001" />
      <inertia
        ixx="0.00001"
        ixy="-8.9555E-06"
        ixz="-2.1884E-05"
        iyy="0.00001"
        iyz="-1.9325E-05"
        izz="0.00001" />
    </inertial>
  </link>
  <joint
    name="J_RLEG2_BACK"
    type="revolute">
    <origin
      xyz="0 0 0"
      rpy="0 0 0" />
    <parent
      link="RLEG2" />
    <child
      link="RLEG2_BACK" />
    <axis
      xyz="0 0 1" />
    <limit
      upper="0.01"
      lower="0.01"
      effort="10"
      velocity="8.58" />
        <dynamics 
     damping="0.7"
     friction="0.5"/>
  </joint>

  
  <link
    name="RLEG3">
    <inertial>
      <origin
        xyz="0.093861 0.021121 -0.026686"
        rpy="0 0 0" />
      <mass
        value="0.25346" />
      <inertia
        ixx="0.00115789"
        ixy="4.3351E-06"
        ixz="2.3814E-06"
        iyy="0.00121525"
        iyz="4.4961E-06"
        izz="0.001" />
    </inertial>
    <visual>
      <origin
        xyz="0 0 0"
        rpy="0 0 0" />
      <geometry>
        <mesh
          filename="package://sakura_description/meshes/RLEG3.STL" />
      </geometry>
      <material
        name="">
        <color
          rgba="0.75294 0.75294 0.75294 1" />
      </material>
    </visual>
  </link>
  <joint
    name="J_RLEG3"
    type="continuous">
    <origin
      xyz="0.112429978208668 -0.169643181644253 0.00160000000000014"
      rpy="-0.0320557226319534 0.0283578707512146 -1.01721646459286" />
    <parent
      link="RLEG2_BACK" />
    <child
      link="RLEG3" />
    <axis
      xyz="0.0283540701513948 0.0320373469653193 -0.999084408398647" />
    <limit
      effort="10"
      velocity="8.58" />
        <dynamics 
     damping="0.7"
     friction="0.5"/>
  </joint>
    <link
    name="RLEG3_BACK">
    <inertial>
      <origin
        xyz="0 0 0"
        rpy="0 0 0" />
      <mass
        value="0.001" />
      <inertia
        ixx="0.00001"
        ixy="-8.9555E-06"
        ixz="-2.1884E-05"
        iyy="0.00001"
        iyz="-1.9325E-05"
        izz="0.00001" />
    </inertial>
  </link>
  <joint
    name="J_RLEG3_BACK"
    type="revolute">
    <origin
      xyz="0 0 0"
      rpy="0 0 0" />
    <parent
      link="RLEG3" />
    <child
      link="RLEG3_BACK" />
    <axis
      xyz="0 0 1" />
    <limit
      upper="0.01"
      lower="0.01"
      effort="10"
      velocity="8.58" />
        <dynamics 
     damping="0.7"
     friction="0.5"/>
  </joint>

  
  <link
    name="RLEG4">
    <inertial>
      <origin
        xyz="0.0207692569273853 -0.014933566350856 -0.0309509783436903"
        rpy="0 0 0" />
      <mass
        value="0.484317524341268" />
      <inertia
        ixx="0.001"
        ixy="8.86337248194835E-06"
        ixz="4.93107012410999E-07"
        iyy="0.001256538006237082"
        iyz="1.08430216395282E-08"
        izz="0.001258532465487085" />
    </inertial>
    <visual>
      <origin
        xyz="0 0 0"
        rpy="0 0 0" />
      <geometry>
        <mesh
          filename="package://sakura_description/meshes/RLEG4.STL" />
      </geometry>
      <material
        name="">
        <color
          rgba="0.752941176470588 0.752941176470588 0.752941176470588 1" />
      </material>
    </visual>
  </link>
  <joint
    name="J_RLEG4"
    type="continuous">
    <origin
      xyz="0.19759 0.040682 0.007913"
      rpy="0.034963 0.024684 -1.339" />
    <parent
      link="RLEG3_BACK" />
    <child
      link="RLEG4" />
    <axis
      xyz="0 0 1" />
    <limit
      effort="10"
      velocity="8.58" />
        <dynamics 
     damping="0.7"
     friction="0.5"/>
  </joint>
  
  <link
    name="RLEG4_BACK">
    <inertial>
      <origin
        xyz="0 0 0"
        rpy="0 0 0" />
      <mass
        value="0.001" />
      <inertia
        ixx="0.00001"
        ixy="-8.9555E-06"
        ixz="-2.1884E-05"
        iyy="0.00001"
        iyz="-1.9325E-05"
        izz="0.00001" />
    </inertial>
  </link>
  <joint
    name="J_RLEG4_BACK"
    type="revolute">
    <origin
      xyz="0 0 0"
      rpy="0 0 0" />
    <parent
      link="RLEG4" />
    <child
      link="RLEG4_BACK" />
    <axis
      xyz="0 0 1" />
    <limit
      upper="0.01"
      lower="0.01"
      effort="10"
      velocity="8.58" />
        <dynamics 
     damping="0.1"
     friction="0.1"/>
  </joint>
  
  <link
    name="RFOOT">
    <inertial>
      <origin
        xyz="0.009844 0.033081 0.074242"
        rpy="0 0 0" />
      <mass
        value="0.47483" />
      <inertia
        ixx="0.001"
        ixy="-8.9555E-06"
        ixz="-2.1884E-05"
        iyy="0.001"
        iyz="-1.9325E-05"
        izz="0.001" />
    </inertial>
    <visual>
      <origin
        xyz="0 0 0"
        rpy="0 0 0" />
      <geometry>
        <mesh
          filename="package://sakura_description/meshes/RFOOT.STL" />
      </geometry>
      <material
        name="">
        <color
          rgba="0.75294 0.75294 0.75294 1" />
      </material>
    </visual>
    <collision>
      <origin
        xyz="0 0 0"
        rpy="0 0 0" />
      <geometry>
        <mesh
          filename="package://sakura_description/meshes/RFOOT.STL" />
      </geometry>
    </collision>
  </link>
  <joint
    name="J_RFOOT"
    type="continuous">
    <origin
      xyz="0.072 0 -0.031"
      rpy="0 -1.5708 0" />
    <parent
      link="RLEG4_BACK" />
    <child
      link="RFOOT" />
    <axis
      xyz="0 0 -1" />
    <limit
      effort="10"
      velocity="8.58" />
        <dynamics 
     damping="0.7"
     friction="0.5"/>
  </joint>
  
  <transmission name="T_RARM0">
	<type>transmission_interface/SimpleTransmission</type>
	<joint name="J_RARM0">
	  <hardwareInterface>hardware_interface/EffortJointInterface</hardwareInterface>
	</joint>
	<actuator name="M_RARM0">
	  <hardwareInterface>hardware_interface/EffortJointInterface</hardwareInterface>
	  <mechanicalReduction>1</mechanicalReduction>
	</actuator>
  </transmission>

  <transmission name="T_RARM1">
	<type>transmission_interface/SimpleTransmission</type>
	<joint name="J_RARM1">
	  <hardwareInterface>hardware_interface/EffortJointInterface</hardwareInterface>
	</joint>
	<actuator name="M_RARM1">
	  <hardwareInterface>hardware_interface/EffortJointInterface</hardwareInterface>
	  <mechanicalReduction>1</mechanicalReduction>
	</actuator>
  </transmission>
  
    <transmission name="T_RARM2">
	<type>transmission_interface/SimpleTransmission</type>
	<joint name="J_RARM2">
	  <hardwareInterface>hardware_interface/EffortJointInterface</hardwareInterface>
	</joint>
	<actuator name="M_RARM2">
	  <hardwareInterface>hardware_interface/EffortJointInterface</hardwareInterface>
	  <mechanicalReduction>1</mechanicalReduction>
	</actuator>
  </transmission>
  
    <transmission name="T_LARM0">
	<type>transmission_interface/SimpleTransmission</type>
	<joint name="J_LARM0">
	  <hardwareInterface>hardware_interface/EffortJointInterface</hardwareInterface>
	</joint>
	<actuator name="M_LARM0">
	  <hardwareInterface>hardware_interface/EffortJointInterface</hardwareInterface>
	  <mechanicalReduction>1</mechanicalReduction>
	</actuator>
  </transmission>

  <transmission name="T_LARM1">
	<type>transmission_interface/SimpleTransmission</type>
	<joint name="J_LARM1">
	  <hardwareInterface>hardware_interface/EffortJointInterface</hardwareInterface>
	</joint>
	<actuator name="M_LARM1">
	  <hardwareInterface>hardware_interface/EffortJointInterface</hardwareInterface>
	  <mechanicalReduction>1</mechanicalReduction>
	</actuator>
  </transmission>
  
    <transmission name="T_LARM2">
	<type>transmission_interface/SimpleTransmission</type>
	<joint name="J_LARM2">
	  <hardwareInterface>hardware_interface/EffortJointInterface</hardwareInterface>
	</joint>
	<actuator name="M_LARM2">
	  <hardwareInterface>hardware_interface/EffortJointInterface</hardwareInterface>
	  <mechanicalReduction>1</mechanicalReduction>
	</actuator>
  </transmission>

  
  
  
    <transmission name="T_RLEG0">
	<type>transmission_interface/SimpleTransmission</type>
	<joint name="J_RLEG0">
	  <hardwareInterface>hardware_interface/EffortJointInterface</hardwareInterface>
	</joint>
	<actuator name="M_RLEG0">
	  <hardwareInterface>hardware_interface/EffortJointInterface</hardwareInterface>
	  <mechanicalReduction>1</mechanicalReduction>
	</actuator>
  </transmission>

  <transmission name="T_RLEG1">
	<type>transmission_interface/SimpleTransmission</type>
	<joint name="J_RLEG1">
	  <hardwareInterface>hardware_interface/EffortJointInterface</hardwareInterface>
	</joint>
	<actuator name="M_RLEG1">
	  <hardwareInterface>hardware_interface/EffortJointInterface</hardwareInterface>
	  <mechanicalReduction>1</mechanicalReduction>
	</actuator>
  </transmission>
  
    <transmission name="T_RLEG2">
	<type>transmission_interface/SimpleTransmission</type>
	<joint name="J_RLEG2">
	  <hardwareInterface>hardware_interface/EffortJointInterface</hardwareInterface>
	</joint>
	<actuator name="M_RLEG2">
	  <hardwareInterface>hardware_interface/EffortJointInterface</hardwareInterface>
	  <mechanicalReduction>1</mechanicalReduction>
	</actuator>
  </transmission>
  
    <transmission name="T_RLEG3">
	<type>transmission_interface/SimpleTransmission</type>
	<joint name="J_RLEG3">
	  <hardwareInterface>hardware_interface/EffortJointInterface</hardwareInterface>
	</joint>
	<actuator name="M_RLEG3">
	  <hardwareInterface>hardware_interface/EffortJointInterface</hardwareInterface>
	  <mechanicalReduction>1</mechanicalReduction>
	</actuator>
  </transmission>
  
   <transmission name="T_RLEG4">
	<type>transmission_interface/SimpleTransmission</type>
	<joint name="J_RLEG4">
	  <hardwareInterface>hardware_interface/EffortJointInterface</hardwareInterface>
	</joint>
	<actuator name="M_RLEG4">
	  <hardwareInterface>hardware_interface/EffortJointInterface</hardwareInterface>
	  <mechanicalReduction>1</mechanicalReduction>
	</actuator>
  </transmission>
  
  <transmission name="T_RFOOT">
	<type>transmission_interface/SimpleTransmission</type>
	<joint name="J_RFOOT">
	  <hardwareInterface>hardware_interface/EffortJointInterface</hardwareInterface>
	</joint>
	<actuator name="M_RFOOT">
	  <hardwareInterface>hardware_interface/EffortJointInterface</hardwareInterface>
	  <mechanicalReduction>1</mechanicalReduction>
	</actuator>
  </transmission>


    <transmission name="T_LLEG0">
	<type>transmission_interface/SimpleTransmission</type>
	<joint name="J_LLEG0">
	  <hardwareInterface>hardware_interface/EffortJointInterface</hardwareInterface>
	</joint>
	<actuator name="M_LLEG0">
	  <hardwareInterface>hardware_interface/EffortJointInterface</hardwareInterface>
	  <mechanicalReduction>1</mechanicalReduction>
	</actuator>
  </transmission>

  <transmission name="T_LLEG1">
	<type>transmission_interface/SimpleTransmission</type>
	<joint name="J_LLEG1">
	  <hardwareInterface>hardware_interface/EffortJointInterface</hardwareInterface>
	</joint>
	<actuator name="M_LLEG1">
	  <hardwareInterface>hardware_interface/EffortJointInterface</hardwareInterface>
	  <mechanicalReduction>1</mechanicalReduction>
	</actuator>
  </transmission>
  
    <transmission name="T_LLEG2">
	<type>transmission_interface/SimpleTransmission</type>
	<joint name="J_LLEG2">
	  <hardwareInterface>hardware_interface/EffortJointInterface</hardwareInterface>
	</joint>
	<actuator name="M_LLEG2">
	  <hardwareInterface>hardware_interface/EffortJointInterface</hardwareInterface>
	  <mechanicalReduction>1</mechanicalReduction>
	</actuator>
  </transmission>
  
    <transmission name="T_LLEG3">
	<type>transmission_interface/SimpleTransmission</type>
	<joint name="J_LLEG3">
	  <hardwareInterface>hardware_interface/EffortJointInterface</hardwareInterface>
	</joint>
	<actuator name="M_LLEG3">
	  <hardwareInterface>hardware_interface/EffortJointInterface</hardwareInterface>
	  <mechanicalReduction>1</mechanicalReduction>
	</actuator>
  </transmission>
  
   <transmission name="T_LLEG4">
	<type>transmission_interface/SimpleTransmission</type>
	<joint name="J_LLEG4">
	  <hardwareInterface>hardware_interface/EffortJointInterface</hardwareInterface>
	</joint>
	<actuator name="M_LLEG4">
	  <hardwareInterface>hardware_interface/EffortJointInterface</hardwareInterface>
	  <mechanicalReduction>1</mechanicalReduction>
	</actuator>
  </transmission>
  
  <transmission name="T_LFOOT">
	<type>transmission_interface/SimpleTransmission</type>
	<joint name="J_LFOOT">
	  <hardwareInterface>hardware_interface/EffortJointInterface</hardwareInterface>
	</joint>
	<actuator name="M_LFOOT">
	  <hardwareInterface>hardware_interface/EffortJointInterface</hardwareInterface>
	  <mechanicalReduction>1</mechanicalReduction>
	</actuator>
  </transmission>



  
</robot>
